Workbook

Sheet 摘要
A1: 結構模型評鑑摘要
A3: 假設路徑 | B3: β | C3: Bootstrap SE | D3: t | E3: p | F3: 95% CI 下界 | G3: 95% CI 上界 | H3: f² | I3: 效果 | J3: 顯著性
A4: ENG → SAT | B4: =5_Bootstrap!B5 -> 0.33502103 | C4: =5_Bootstrap!D5 -> 0.15043623 | D4: =5_Bootstrap!E5 -> 2.2269969 | E4: =5_Bootstrap!F5 -> 0.026392897 | F4: =5_Bootstrap!G5 -> -0.024030073 | G4: =5_Bootstrap!H5 -> 0.60250242 | H4: =3_f2!G5 -> 0.17524957 | I4: =3_f2!H5 -> 中 | J4: =5_Bootstrap!I5 -> 不一致：審慎解讀
A5: TQ → SAT | B5: =5_Bootstrap!B6 -> 0.48976718 | C5: =5_Bootstrap!D6 -> 0.16534751 | D5: =5_Bootstrap!E6 -> 2.9620475 | E5: =5_Bootstrap!F6 -> 0.0032017356 | F5: =5_Bootstrap!G6 -> 0.12589896 | G5: =5_Bootstrap!H6 -> 0.79994983 | H5: =3_f2!G6 -> 0.3745348 | I5: =3_f2!H6 -> 大 | J5: =5_Bootstrap!I6 -> 顯著
A6: TQ → INT | B6: =5_Bootstrap!B7 -> 0.15538053 | C6: =5_Bootstrap!D7 -> 0.16101361 | D6: =5_Bootstrap!E7 -> 0.96501485 | E6: =5_Bootstrap!F7 -> 0.33500481 | F6: =5_Bootstrap!G7 -> -0.20757997 | G6: =5_Bootstrap!H7 -> 0.44151448 | H6: =3_f2!G7 -> 0.023820873 | I6: =3_f2!H7 -> 小 | J6: =5_Bootstrap!I7 -> 不顯著
A7: SAT → INT | B7: =5_Bootstrap!B8 -> 0.53520369 | C7: =5_Bootstrap!D8 -> 0.16930606 | D7: =5_Bootstrap!E8 -> 3.1611609 | E7: =5_Bootstrap!F8 -> 0.001666947 | F7: =5_Bootstrap!G8 -> 0.12610349 | G7: =5_Bootstrap!H8 -> 0.7947922 | H7: =3_f2!G8 -> 0.28261987 | I7: =3_f2!H8 -> 中 | J7: =5_Bootstrap!I8 -> 顯著
A10: 內生構念 | B10: R² | C10: 調整後 R² | D10: 解釋力 | E10: Q²
A11: SAT（學習滿意度） | B11: =2_路徑與R2!B18 -> 0.51246302 | C11: =2_路徑與R2!C18 -> 0.47634917 | D11: =2_路徑與R2!F18 -> 中度 | E11: =4_Q2!B50 -> 0.3963324
A12: INT（持續學習意願） | B12: =2_路徑與R2!B19 -> 0.41927145 | C12: =2_路徑與R2!C19 -> 0.37625452 | D12: =2_路徑與R2!F19 -> 低度 | E12: =4_Q2!P50 -> 0.2784395
A14: GoF（僅供參考） | B14: =6_GoF!B12 -> 0.61438344
A16: 綠字為連結至其他工作表之公式。

Sheet 原始資料
A1: 原始資料：4 個構念 × 3 題，5 點李克特量表，n = 30
A2: ENG=學習投入；TQ=教學品質；SAT=學習滿意度；INT=持續學習意願。藍字為輸入值（教學用模擬資料）。
A4: 受試者 | B4: ENG1 | C4: ENG2 | D4: ENG3 | E4: TQ1 | F4: TQ2 | G4: TQ3 | H4: SAT1 | I4: SAT2 | J4: SAT3 | K4: INT1 | L4: INT2 | M4: INT3
A5: R01 | B5: 4 | C5: 4 | D5: 4 | E5: 4 | F5: 4 | G5: 3 | H5: 4 | I5: 3 | J5: 4 | K5: 3 | L5: 3 | M5: 3
A6: R02 | B6: 3 | C6: 3 | D6: 5 | E6: 4 | F6: 4 | G6: 4 | H6: 3 | I6: 3 | J6: 3 | K6: 3 | L6: 3 | M6: 3
A7: R03 | B7: 3 | C7: 4 | D7: 3 | E7: 2 | F7: 2 | G7: 2 | H7: 4 | I7: 3 | J7: 4 | K7: 4 | L7: 3 | M7: 3
A8: R04 | B8: 3 | C8: 3 | D8: 4 | E8: 3 | F8: 4 | G8: 4 | H8: 4 | I8: 4 | J8: 4 | K8: 3 | L8: 3 | M8: 4
A9: R05 | B9: 2 | C9: 3 | D9: 3 | E9: 4 | F9: 4 | G9: 4 | H9: 3 | I9: 3 | J9: 3 | K9: 2 | L9: 2 | M9: 3
A10: R06 | B10: 2 | C10: 2 | D10: 3 | E10: 3 | F10: 3 | G10: 3 | H10: 2 | I10: 3 | J10: 3 | K10: 3 | L10: 3 | M10: 2
A11: R07 | B11: 4 | C11: 4 | D11: 3 | E11: 2 | F11: 3 | G11: 3 | H11: 2 | I11: 3 | J11: 2 | K11: 2 | L11: 3 | M11: 3
A12: R08 | B12: 3 | C12: 3 | D12: 3 | E12: 4 | F12: 3 | G12: 4 | H12: 5 | I12: 4 | J12: 3 | K12: 2 | L12: 2 | M12: 3
A13: R09 | B13: 4 | C13: 4 | D13: 3 | E13: 4 | F13: 4 | G13: 4 | H13: 4 | I13: 4 | J13: 4 | K13: 4 | L13: 4 | M13: 3
A14: R10 | B14: 3 | C14: 2 | D14: 2 | E14: 3 | F14: 4 | G14: 3 | H14: 3 | I14: 4 | J14: 4 | K14: 3 | L14: 3 | M14: 3
A15: R11 | B15: 5 | C15: 5 | D15: 4 | E15: 3 | F15: 3 | G15: 3 | H15: 5 | I15: 4 | J15: 5 | K15: 4 | L15: 4 | M15: 4
A16: R12 | B16: 2 | C16: 3 | D16: 2 | E16: 3 | F16: 3 | G16: 3 | H16: 4 | I16: 3 | J16: 3 | K16: 4 | L16: 4 | M16: 4
... A34: R30 | B34: 4 | C34: 4 | D34: 4 | E34: 3 | F34: 4 | G34: 3 | H34: 4 | I34: 4 | J34: 4 | K34: 4 | L34: 4 | M34: 3

Sheet 1_構念分數
A1: 步驟 0：構念分數（LV scores）與 AVE
A2: 構念分數 = 各題 Z 分數平均後再標準化（平均 0、標準差 1），作為結構模型迴歸之輸入（教學近似，同 3.2、3.3 節）。
A4: 受試者 | B4: ENG1 | C4: ENG2 | D4: ENG3 | E4: TQ1 | F4: TQ2 | G4: TQ3 | H4: SAT1 | I4: SAT2 | J4: SAT3 | K4: INT1 | L4: INT2 | M4: INT3 | N4: Z_ENG1 | O4: Z_ENG2 | P4: Z_ENG3 | Q4: Z_TQ1 | R4: Z_TQ2 | S4: Z_TQ3 | T4: Z_SAT1 | U4: Z_SAT2 | V4: Z_SAT3 | W4: Z_INT1 | X4: Z_INT2 | Y4: Z_INT3 | Z4: ENG 平均Z | AA4: TQ 平均Z | AB4: SAT 平均Z | AC4: INT 平均Z | AD4: ENG 分數 | AE4: TQ 分數 | AF4: SAT 分數 | AG4: INT 分數
A5: =原始資料!A5 -> R01 | B5: =原始資料!B5 -> 4 | C5: =原始資料!C5 -> 4 | D5: =原始資料!D5 -> 4 | E5: =原始資料!E5 -> 4 | F5: =原始資料!F5 -> 4 | G5: =原始資料!G5 -> 3 | H5: =原始資料!H5 -> 4 | ... M5: =原始資料!M5 -> 3 | N5: =STANDARDIZE(B5,AVERAGE(B$5:B$34),STDEV(B$5:B$34)) -> 0.51877624 | O5: =STANDARDIZE(C5,AVERAGE(C$5:C$34),STDEV(C$5:C$34)) -> 0.60589165 | P5: =STANDARDIZE(D5,AVERAGE(D$5:D$34),STDEV(D$5:D$34)) -> 0.66017379 | Q5: =STANDARDIZE(E5,AVERAGE(E$5:E$34),STDEV(E$5:E$34)) -> 0.73739406 | R5: =STANDARDIZE(F5,AVERAGE(F$5:F$34),STDEV(F$5:F$34)) -> 0.78971888 | S5: =STANDARDIZE(G5,AVERAGE(G$5:G$34),STDEV(G$5:G$34)) -> -0.32773069 | T5: =STANDARDIZE(H5,AVERAGE(H$5:H$34),STDEV(H$5:H$34)) -> 0.57845949 | U5: =STANDARDIZE(I5,AVERAGE(I$5:I$34),STDEV(I$5:I$34)) -> -0.3614286 | ... Y5: =STANDARDIZE(M5,AVERAGE(M$5:M$34),STDEV(M$5:M$34)) -> -0.32218493 | Z5: =AVERAGE(N5:P5) -> 0.59494723 | AA5: =AVERAGE(Q5:S5) -> 0.39979408 | AB5: =AVERAGE(T5:V5) -> 0.30956899 | AC5: =AVERAGE(W5:Y5) -> -0.24904263 | AD5: =STANDARDIZE(Z5,AVERAGE(Z$5:Z$34),STDEV(Z$5:Z$34)) -> 0.67614559 | AE5: =STANDARDIZE(AA5,AVERAGE(AA$5:AA$34),STDEV(AA$5:AA$34)) -> 0.43696497 | AF5: =STANDARDIZE(AB5,AVERAGE(AB$5:AB$34),STDEV(AB$5:AB$34)) -> 0.34550282 | AG5: =STANDARDIZE(AC5,AVERAGE(AC$5:AC$34),STDEV(AC$5:AC$34)) -> -0.2741407
A6: =原始資料!A6 -> R02 | B6: =原始資料!B6 -> 3 | C6: =原始資料!C6 -> 3 | D6: =原始資料!D6 -> 5 | E6: =原始資料!E6 -> 4 | F6: =原始資料!F6 -> 4 | G6: =原始資料!G6 -> 4 | H6: =原始資料!H6 -> 3 | ... M6: =原始資料!M6 -> 3 | N6: =STANDARDIZE(B6,AVERAGE(B$5:B$34),STDEV(B$5:B$34)) -> -0.59288713 | O6: =STANDARDIZE(C6,AVERAGE(C$5:C$34),STDEV(C$5:C$34)) -> -0.46332891 | P6: =STANDARDIZE(D6,AVERAGE(D$5:D$34),STDEV(D$5:D$34)) -> 1.8251864 | Q6: =STANDARDIZE(E6,AVERAGE(E$5:E$34),STDEV(E$5:E$34)) -> 0.73739406 | R6: =STANDARDIZE(F6,AVERAGE(F$5:F$34),STDEV(F$5:F$34)) -> 0.78971888 | S6: =STANDARDIZE(G6,AVERAGE(G$5:G$34),STDEV(G$5:G$34)) -> 0.76470495 | T6: =STANDARDIZE(H6,AVERAGE(H$5:H$34),STDEV(H$5:H$34)) -> -0.38563966 | U6: =STANDARDIZE(I6,AVERAGE(I$5:I$34),STDEV(I$5:I$34)) -> -0.3614286 | ... Y6: =STANDARDIZE(M6,AVERAGE(M$5:M$34),STDEV(M$5:M$34)) -> -0.32218493 | Z6: =AVERAGE(N6:P6) -> 0.25632344 | AA6: =AVERAGE(Q6:S6) -> 0.7639393 | AB6: =AVERAGE(T6:V6) -> -0.38636375 | AC6: =AVERAGE(W6:Y6) -> -0.24904263 | AD6: =STANDARDIZE(Z6,AVERAGE(Z$5:Z$34),STDEV(Z$5:Z$34)) -> 0.29130645 | AE6: =STANDARDIZE(AA6,AVERAGE(AA$5:AA$34),STDEV(AA$5:AA$34)) -> 0.83496662 | AF6: =STANDARDIZE(AB6,AVERAGE(AB$5:AB$34),STDEV(AB$5:AB$34)) -> -0.43121169 | AG6: =STANDARDIZE(AC6,AVERAGE(AC$5:AC$34),STDEV(AC$5:AC$34)) -> -0.2741407
A7: =原始資料!A7 -> R03 | B7: =原始資料!B7 -> 3 | C7: =原始資料!C7 -> 4 | D7: =原始資料!D7 -> 3 | E7: =原始資料!E7 -> 2 | F7: =原始資料!F7 -> 2 | G7: =原始資料!G7 -> 2 | H7: =原始資料!H7 -> 4 | ... M7: =原始資料!M7 -> 3 | N7: =STANDARDIZE(B7,AVERAGE(B$5:B$34),STDEV(B$5:B$34)) -> -0.59288713 | O7: =STANDARDIZE(C7,AVERAGE(C$5:C$34),STDEV(C$5:C$34)) -> 0.60589165 | P7: =STANDARDIZE(D7,AVERAGE(D$5:D$34),STDEV(D$5:D$34)) -> -0.50483878 | Q7: =STANDARDIZE(E7,AVERAGE(E$5:E$34),STDEV(E$5:E$34)) -> -1.7205861 | R7: =STANDARDIZE(F7,AVERAGE(F$5:F$34),STDEV(F$5:F$34)) -> -1.5794378 | S7: =STANDARDIZE(G7,AVERAGE(G$5:G$34),STDEV(G$5:G$34)) -> -1.4201663 | T7: =STANDARDIZE(H7,AVERAGE(H$5:H$34),STDEV(H$5:H$34)) -> 0.57845949 | U7: =STANDARDIZE(I7,AVERAGE(I$5:I$34),STDEV(I$5:I$34)) -> -0.3614286 | ... Y7: =STANDARDIZE(M7,AVERAGE(M$5:M$34),STDEV(M$5:M$34)) -> -0.32218493 | Z7: =AVERAGE(N7:P7) -> -0.16394476 | AA7: =AVERAGE(Q7:S7) -> -1.5733967 | AB7: =AVERAGE(T7:V7) -> 0.30956899 | AC7: =AVERAGE(W7:Y7) -> 0.10736422 | AD7: =STANDARDIZE(Z7,AVERAGE(Z$5:Z$34),STDEV(Z$5:Z$34)) -> -0.18631993 | AE7: =STANDARDIZE(AA7,AVERAGE(AA$5:AA$34),STDEV(AA$5:AA$34)) -> -1.7196834 | AF7: =STANDARDIZE(AB7,AVERAGE(AB$5:AB$34),STDEV(AB$5:AB$34)) -> 0.34550282 | AG7: =STANDARDIZE(AC7,AVERAGE(AC$5:AC$34),STDEV(AC$5:AC$34)) -> 0.1181842
A8: =原始資料!A8 -> R04 | B8: =原始資料!B8 -> 3 | C8: =原始資料!C8 -> 3 | D8: =原始資料!D8 -> 4 | E8: =原始資料!E8 -> 3 | F8: =原始資料!F8 -> 4 | G8: =原始資料!G8 -> 4 | H8: =原始資料!H8 -> 4 | ... M8: =原始資料!M8 -> 4 | N8: =STANDARDIZE(B8,AVERAGE(B$5:B$34),STDEV(B$5:B$34)) -> -0.59288713 | O8: =STANDARDIZE(C8,AVERAGE(C$5:C$34),STDEV(C$5:C$34)) -> -0.46332891 | P8: =STANDARDIZE(D8,AVERAGE(D$5:D$34),STDEV(D$5:D$34)) -> 0.66017379 | Q8: =STANDARDIZE(E8,AVERAGE(E$5:E$34),STDEV(E$5:E$34)) -> -0.49159604 | R8: =STANDARDIZE(F8,AVERAGE(F$5:F$34),STDEV(F$5:F$34)) -> 0.78971888 | S8: =STANDARDIZE(G8,AVERAGE(G$5:G$34),STDEV(G$5:G$34)) -> 0.76470495 | T8: =STANDARDIZE(H8,AVERAGE(H$5:H$34),STDEV(H$5:H$34)) -> 0.57845949 | U8: =STANDARDIZE(I8,AVERAGE(I$5:I$34),STDEV(I$5:I$34)) -> 0.72285719 | ... Y8: =STANDARDIZE(M8,AVERAGE(M$5:M$34),STDEV(M$5:M$34)) -> 0.88600857 | Z8: =AVERAGE(N8:P8) -> -0.13201408 | AA8: =AVERAGE(Q8:S8) -> 0.35427593 | AB8: =AVERAGE(T8:V8) -> 0.67099758 | AC8: =AVERAGE(W8:Y8) -> 0.15368854 | AD8: =STANDARDIZE(Z8,AVERAGE(Z$5:Z$34),STDEV(Z$5:Z$34)) -> -0.15003136 | AE8: =STANDARDIZE(AA8,AVERAGE(AA$5:AA$34),STDEV(AA$5:AA$34)) -> 0.38721477 | AF8: =STANDARDIZE(AB8,AVERAGE(AB$5:AB$34),STDEV(AB$5:AB$34)) -> 0.74888497 | AG8: =STANDARDIZE(AC8,AVERAGE(AC$5:AC$34),STDEV(AC$5:AC$34)) -> 0.169177
A9: =原始資料!A9 -> R05 | B9: =原始資料!B9 -> 2 | C9: =原始資料!C9 -> 3 | D9: =原始資料!D9 -> 3 | E9: =原始資料!E9 -> 4 | F9: =原始資料!F9 -> 4 | G9: =原始資料!G9 -> 4 | H9: =原始資料!H9 -> 3 | ... M9: =原始資料!M9 -> 3 | N9: =STANDARDIZE(B9,AVERAGE(B$5:B$34),STDEV(B$5:B$34)) -> -1.7045505 | O9: =STANDARDIZE(C9,AVERAGE(C$5:C$34),STDEV(C$5:C$34)) -> -0.46332891 | P9: =STANDARDIZE(D9,AVERAGE(D$5:D$34),STDEV(D$5:D$34)) -> -0.50483878 | Q9: =STANDARDIZE(E9,AVERAGE(E$5:E$34),STDEV(E$5:E$34)) -> 0.73739406 | R9: =STANDARDIZE(F9,AVERAGE(F$5:F$34),STDEV(F$5:F$34)) -> 0.78971888 | S9: =STANDARDIZE(G9,AVERAGE(G$5:G$34),STDEV(G$5:G$34)) -> 0.76470495 | T9: =STANDARDIZE(H9,AVERAGE(H$5:H$34),STDEV(H$5:H$34)) -> -0.38563966 | U9: =STANDARDIZE(I9,AVERAGE(I$5:I$34),STDEV(I$5:I$34)) -> -0.3614286 | ... Y9: =STANDARDIZE(M9,AVERAGE(M$5:M$34),STDEV(M$5:M$34)) -> -0.32218493 | Z9: =AVERAGE(N9:P9) -> -0.89090606 | AA9: =AVERAGE(Q9:S9) -> 0.7639393 | AB9: =AVERAGE(T9:V9) -> -0.38636375 | AC9: =AVERAGE(W9:Y9) -> -0.95636578 | AD9: =STANDARDIZE(Z9,AVERAGE(Z$5:Z$34),STDEV(Z$5:Z$34)) -> -1.0124969 | AE9: =STANDARDIZE(AA9,AVERAGE(AA$5:AA$34),STDEV(AA$5:AA$34)) -> 0.83496662 | AF9: =STANDARDIZE(AB9,AVERAGE(AB$5:AB$34),STDEV(AB$5:AB$34)) -> -0.43121169 | AG9: =STANDARDIZE(AC9,AVERAGE(AC$5:AC$34),STDEV(AC$5:AC$34)) -> -1.0527466
A10: =原始資料!A10 -> R06 | B10: =原始資料!B10 -> 2 | C10: =原始資料!C10 -> 2 | D10: =原始資料!D10 -> 3 | E10: =原始資料!E10 -> 3 | F10: =原始資料!F10 -> 3 | G10: =原始資料!G10 -> 3 | H10: =原始資料!H10 -> 2 | ... M10: =原始資料!M10 -> 2 | N10: =STANDARDIZE(B10,AVERAGE(B$5:B$34),STDEV(B$5:B$34)) -> -1.7045505 | O10: =STANDARDIZE(C10,AVERAGE(C$5:C$34),STDEV(C$5:C$34)) -> -1.5325495 | P10: =STANDARDIZE(D10,AVERAGE(D$5:D$34),STDEV(D$5:D$34)) -> -0.50483878 | Q10: =STANDARDIZE(E10,AVERAGE(E$5:E$34),STDEV(E$5:E$34)) -> -0.49159604 | R10: =STANDARDIZE(F10,AVERAGE(F$5:F$34),STDEV(F$5:F$34)) -> -0.39485944 | S10: =STANDARDIZE(G10,AVERAGE(G$5:G$34),STDEV(G$5:G$34)) -> -0.32773069 | T10: =STANDARDIZE(H10,AVERAGE(H$5:H$34),STDEV(H$5:H$34)) -> -1.3497388 | U10: =STANDARDIZE(I10,AVERAGE(I$5:I$34),STDEV(I$5:I$34)) -> -0.3614286 | ... Y10: =STANDARDIZE(M10,AVERAGE(M$5:M$34),STDEV(M$5:M$34)) -> -1.5303784 | Z10: =AVERAGE(N10:P10) -> -1.2473129 | AA10: =AVERAGE(Q10:S10) -> -0.40472872 | AB10: =AVERAGE(T10:V10) -> -0.70773013 | AC10: =AVERAGE(W10:Y10) -> -0.65177379 | AD10: =STANDARDIZE(Z10,AVERAGE(Z$5:Z$34),STDEV(Z$5:Z$34)) -> -1.4175461 | AE10: =STANDARDIZE(AA10,AVERAGE(AA$5:AA$34),STDEV(AA$5:AA$34)) -> -0.44235841 | AF10: =STANDARDIZE(AB10,AVERAGE(AB$5:AB$34),STDEV(AB$5:AB$34)) -> -0.78988132 | AG10: =STANDARDIZE(AC10,AVERAGE(AC$5:AC$34),STDEV(AC$5:AC$34)) -> -0.71745841
A11: =原始資料!A11 -> R07 | B11: =原始資料!B11 -> 4 | C11: =原始資料!C11 -> 4 | D11: =原始資料!D11 -> 3 | E11: =原始資料!E11 -> 2 | F11: =原始資料!F11 -> 3 | G11: =原始資料!G11 -> 3 | H11: =原始資料!H11 -> 2 | ... M11: =原始資料!M11 -> 3 | N11: =STANDARDIZE(B11,AVERAGE(B$5:B$34),STDEV(B$5:B$34)) -> 0.51877624 | O11: =STANDARDIZE(C11,AVERAGE(C$5:C$34),STDEV(C$5:C$34)) -> 0.60589165 | P11: =STANDARDIZE(D11,AVERAGE(D$5:D$34),STDEV(D$5:D$34)) -> -0.50483878 | Q11: =STANDARDIZE(E11,AVERAGE(E$5:E$34),STDEV(E$5:E$34)) -> -1.7205861 | R11: =STANDARDIZE(F11,AVERAGE(F$5:F$34),STDEV(F$5:F$34)) -> -0.39485944 | S11: =STANDARDIZE(G11,AVERAGE(G$5:G$34),STDEV(G$5:G$34)) -> -0.32773069 | T11: =STANDARDIZE(H11,AVERAGE(H$5:H$34),STDEV(H$5:H$34)) -> -1.3497388 | U11: =STANDARDIZE(I11,AVERAGE(I$5:I$34),STDEV(I$5:I$34)) -> -0.3614286 | ... Y11: =STANDARDIZE(M11,AVERAGE(M$5:M$34),STDEV(M$5:M$34)) -> -0.32218493 | Z11: =AVERAGE(N11:P11) -> 0.2066097 | AA11: =AVERAGE(Q11:S11) -> -0.81439209 | AB11: =AVERAGE(T11:V11) -> -1.0822965 | AC11: =AVERAGE(W11:Y11) -> -0.60544948 | AD11: =STANDARDIZE(Z11,AVERAGE(Z$5:Z$34),STDEV(Z$5:Z$34)) -> 0.23480778 | AE11: =STANDARDIZE(AA11,AVERAGE(AA$5:AA$34),STDEV(AA$5:AA$34)) -> -0.89011027 | AF11: =STANDARDIZE(AB11,AVERAGE(AB$5:AB$34),STDEV(AB$5:AB$34)) -> -1.2079262 | AG11: =STANDARDIZE(AC11,AVERAGE(AC$5:AC$34),STDEV(AC$5:AC$34)) -> -0.6664656
A12: =原始資料!A12 -> R08 | B12: =原始資料!B12 -> 3 | C12: =原始資料!C12 -> 3 | D12: =原始資料!D12 -> 3 | E12: =原始資料!E12 -> 4 | F12: =原始資料!F12 -> 3 | G12: =原始資料!G12 -> 4 | H12: =原始資料!H12 -> 5 | ... M12: =原始資料!M12 -> 3 | N12: =STANDARDIZE(B12,AVERAGE(B$5:B$34),STDEV(B$5:B$34)) -> -0.59288713 | O12: =STANDARDIZE(C12,AVERAGE(C$5:C$34),STDEV(C$5:C$34)) -> -0.46332891 | P12: =STANDARDIZE(D12,AVERAGE(D$5:D$34),STDEV(D$5:D$34)) -> -0.50483878 | Q12: =STANDARDIZE(E12,AVERAGE(E$5:E$34),STDEV(E$5:E$34)) -> 0.73739406 | R12: =STANDARDIZE(F12,AVERAGE(F$5:F$34),STDEV(F$5:F$34)) -> -0.39485944 | S12: =STANDARDIZE(G12,AVERAGE(G$5:G$34),STDEV(G$5:G$34)) -> 0.76470495 | T12: =STANDARDIZE(H12,AVERAGE(H$5:H$34),STDEV(H$5:H$34)) -> 1.5425586 | U12: =STANDARDIZE(I12,AVERAGE(I$5:I$34),STDEV(I$5:I$34)) -> 0.72285719 | ... Y12: =STANDARDIZE(M12,AVERAGE(M$5:M$34),STDEV(M$5:M$34)) -> -0.32218493 | Z12: =AVERAGE(N12:P12) -> -0.52035161 | AA12: =AVERAGE(Q12:S12) -> 0.36907986 | AB12: =AVERAGE(T12:V12) -> 0.61779762 | AC12: =AVERAGE(W12:Y12) -> -0.95636578 | AD12: =STANDARDIZE(Z12,AVERAGE(Z$5:Z$34),STDEV(Z$5:Z$34)) -> -0.59136917 | AE12: =STANDARDIZE(AA12,AVERAGE(AA$5:AA$34),STDEV(AA$5:AA$34)) -> 0.40339509 | AF12: =STANDARDIZE(AB12,AVERAGE(AB$5:AB$34),STDEV(AB$5:AB$34)) -> 0.68950971 | AG12: =STANDARDIZE(AC12,AVERAGE(AC$5:AC$34),STDEV(AC$5:AC$34)) -> -1.0527466
A13: =原始資料!A13 -> R09 | B13: =原始資料!B13 -> 4 | C13: =原始資料!C13 -> 4 | D13: =原始資料!D13 -> 3 | E13: =原始資料!E13 -> 4 | F13: =原始資料!F13 -> 4 | G13: =原始資料!G13 -> 4 | H13: =原始資料!H13 -> 4 | ... M13: =原始資料!M13 -> 3 | N13: =STANDARDIZE(B13,AVERAGE(B$5:B$34),STDEV(B$5:B$34)) -> 0.51877624 | O13: =STANDARDIZE(C13,AVERAGE(C$5:C$34),STDEV(C$5:C$34)) -> 0.60589165 | P13: =STANDARDIZE(D13,AVERAGE(D$5:D$34),STDEV(D$5:D$34)) -> -0.50483878 | Q13: =STANDARDIZE(E13,AVERAGE(E$5:E$34),STDEV(E$5:E$34)) -> 0.73739406 | R13: =STANDARDIZE(F13,AVERAGE(F$5:F$34),STDEV(F$5:F$34)) -> 0.78971888 | S13: =STANDARDIZE(G13,AVERAGE(G$5:G$34),STDEV(G$5:G$34)) -> 0.76470495 | T13: =STANDARDIZE(H13,AVERAGE(H$5:H$34),STDEV(H$5:H$34)) -> 0.57845949 | U13: =STANDARDIZE(I13,AVERAGE(I$5:I$34),STDEV(I$5:I$34)) -> 0.72285719 | ... Y13: =STANDARDIZE(M13,AVERAGE(M$5:M$34),STDEV(M$5:M$34)) -> -0.32218493 | Z13: =AVERAGE(N13:P13) -> 0.2066097 | AA13: =AVERAGE(Q13:S13) -> 0.7639393 | AB13: =AVERAGE(T13:V13) -> 0.67099758 | AC13: =AVERAGE(W13:Y13) -> 0.45828053 | AD13: =STANDARDIZE(Z13,AVERAGE(Z$5:Z$34),STDEV(Z$5:Z$34)) -> 0.23480778 | AE13: =STANDARDIZE(AA13,AVERAGE(AA$5:AA$34),STDEV(AA$5:AA$34)) -> 0.83496662 | AF13: =STANDARDIZE(AB13,AVERAGE(AB$5:AB$34),STDEV(AB$5:AB$34)) -> 0.74888497 | AG13: =STANDARDIZE(AC13,AVERAGE(AC$5:AC$34),STDEV(AC$5:AC$34)) -> 0.50446523
A14: =原始資料!A14 -> R10 | B14: =原始資料!B14 -> 3 | C14: =原始資料!C14 -> 2 | D14: =原始資料!D14 -> 2 | E14: =原始資料!E14 -> 3 | F14: =原始資料!F14 -> 4 | G14: =原始資料!G14 -> 3 | H14: =原始資料!H14 -> 3 | ... M14: =原始資料!M14 -> 3 | N14: =STANDARDIZE(B14,AVERAGE(B$5:B$34),STDEV(B$5:B$34)) -> -0.59288713 | O14: =STANDARDIZE(C14,AVERAGE(C$5:C$34),STDEV(C$5:C$34)) -> -1.5325495 | P14: =STANDARDIZE(D14,AVERAGE(D$5:D$34),STDEV(D$5:D$34)) -> -1.6698514 | Q14: =STANDARDIZE(E14,AVERAGE(E$5:E$34),STDEV(E$5:E$34)) -> -0.49159604 | R14: =STANDARDIZE(F14,AVERAGE(F$5:F$34),STDEV(F$5:F$34)) -> 0.78971888 | S14: =STANDARDIZE(G14,AVERAGE(G$5:G$34),STDEV(G$5:G$34)) -> -0.32773069 | T14: =STANDARDIZE(H14,AVERAGE(H$5:H$34),STDEV(H$5:H$34)) -> -0.38563966 | U14: =STANDARDIZE(I14,AVERAGE(I$5:I$34),STDEV(I$5:I$34)) -> 0.72285719 | ... Y14: =STANDARDIZE(M14,AVERAGE(M$5:M$34),STDEV(M$5:M$34)) -> -0.32218493 | Z14: =AVERAGE(N14:P14) -> -1.265096 | AA14: =AVERAGE(Q14:S14) -> -0.0098692836 | AB14: =AVERAGE(T14:V14) -> 0.3496312 | AC14: =AVERAGE(W14:Y14) -> -0.24904263 | AD14: =STANDARDIZE(Z14,AVERAGE(Z$5:Z$34),STDEV(Z$5:Z$34)) -> -1.4377562 | AE14: =STANDARDIZE(AA14,AVERAGE(AA$5:AA$34),STDEV(AA$5:AA$34)) -> -0.010786881 | AF14: =STANDARDIZE(AB14,AVERAGE(AB$5:AB$34),STDEV(AB$5:AB$34)) -> 0.39021534 | AG14: =STANDARDIZE(AC14,AVERAGE(AC$5:AC$34),STDEV(AC$5:AC$34)) -> -0.2741407
A15: =原始資料!A15 -> R11 | B15: =原始資料!B15 -> 5 | C15: =原始資料!C15 -> 5 | D15: =原始資料!D15 -> 4 | E15: =原始資料!E15 -> 3 | F15: =原始資料!F15 -> 3 | G15: =原始資料!G15 -> 3 | H15: =原始資料!H15 -> 5 | ... M15: =原始資料!M15 -> 4 | N15: =STANDARDIZE(B15,AVERAGE(B$5:B$34),STDEV(B$5:B$34)) -> 1.6304396 | O15: =STANDARDIZE(C15,AVERAGE(C$5:C$34),STDEV(C$5:C$34)) -> 1.6751122 | P15: =STANDARDIZE(D15,AVERAGE(D$5:D$34),STDEV(D$5:D$34)) -> 0.66017379 | Q15: =STANDARDIZE(E15,AVERAGE(E$5:E$34),STDEV(E$5:E$34)) -> -0.49159604 | R15: =STANDARDIZE(F15,AVERAGE(F$5:F$34),STDEV(F$5:F$34)) -> -0.39485944 | S15: =STANDARDIZE(G15,AVERAGE(G$5:G$34),STDEV(G$5:G$34)) -> -0.32773069 | T15: =STANDARDIZE(H15,AVERAGE(H$5:H$34),STDEV(H$5:H$34)) -> 1.5425586 | U15: =STANDARDIZE(I15,AVERAGE(I$5:I$34),STDEV(I$5:I$34)) -> 0.72285719 | ... Y15: =STANDARDIZE(M15,AVERAGE(M$5:M$34),STDEV(M$5:M$34)) -> 0.88600857 | Z15: =AVERAGE(N15:P15) -> 1.3219085 | AA15: =AVERAGE(Q15:S15) -> -0.40472872 | AB15: =AVERAGE(T15:V15) -> 1.3669303 | AC15: =AVERAGE(W15:Y15) -> 0.86101169 | AD15: =STANDARDIZE(Z15,AVERAGE(Z$5:Z$34),STDEV(Z$5:Z$34)) -> 1.5023225 | AE15: =STANDARDIZE(AA15,AVERAGE(AA$5:AA$34),STDEV(AA$5:AA$34)) -> -0.44235841 | AF15: =STANDARDIZE(AB15,AVERAGE(AB$5:AB$34),STDEV(AB$5:AB$34)) -> 1.5255995 | AG15: =STANDARDIZE(AC15,AVERAGE(AC$5:AC$34),STDEV(AC$5:AC$34)) -> 0.94778293
A16: =原始資料!A16 -> R12 | B16: =原始資料!B16 -> 2 | C16: =原始資料!C16 -> 3 | D16: =原始資料!D16 -> 2 | E16: =原始資料!E16 -> 3 | F16: =原始資料!F16 -> 3 | G16: =原始資料!G16 -> 3 | H16: =原始資料!H16 -> 4 | ... M16: =原始資料!M16 -> 4 | N16: =STANDARDIZE(B16,AVERAGE(B$5:B$34),STDEV(B$5:B$34)) -> -1.7045505 | O16: =STANDARDIZE(C16,AVERAGE(C$5:C$34),STDEV(C$5:C$34)) -> -0.46332891 | P16: =STANDARDIZE(D16,AVERAGE(D$5:D$34),STDEV(D$5:D$34)) -> -1.6698514 | Q16: =STANDARDIZE(E16,AVERAGE(E$5:E$34),STDEV(E$5:E$34)) -> -0.49159604 | R16: =STANDARDIZE(F16,AVERAGE(F$5:F$34),STDEV(F$5:F$34)) -> -0.39485944 | S16: =STANDARDIZE(G16,AVERAGE(G$5:G$34),STDEV(G$5:G$34)) -> -0.32773069 | T16: =STANDARDIZE(H16,AVERAGE(H$5:H$34),STDEV(H$5:H$34)) -> 0.57845949 | U16: =STANDARDIZE(I16,AVERAGE(I$5:I$34),STDEV(I$5:I$34)) -> -0.3614286 | ... Y16: =STANDARDIZE(M16,AVERAGE(M$5:M$34),STDEV(M$5:M$34)) -> 0.88600857 | Z16: =AVERAGE(N16:P16) -> -1.2792436 | AA16: =AVERAGE(Q16:S16) -> -0.40472872 | AB16: =AVERAGE(T16:V16) -> -0.064997364 | AC16: =AVERAGE(W16:Y16) -> 0.86101169 | AD16: =STANDARDIZE(Z16,AVERAGE(Z$5:Z$34),STDEV(Z$5:Z$34)) -> -1.4538347 | AE16: =STANDARDIZE(AA16,AVERAGE(AA$5:AA$34),STDEV(AA$5:AA$34)) -> -0.44235841 | AF16: =STANDARDIZE(AB16,AVERAGE(AB$5:AB$34),STDEV(AB$5:AB$34)) -> -0.072542062 | AG16: =STANDARDIZE(AC16,AVERAGE(AC$5:AC$34),STDEV(AC$5:AC$34)) -> 0.94778293
... A34: =原始資料!A34 -> R30 | B34: =原始資料!B34 -> 4 | C34: =原始資料!C34 -> 4 | D34: =原始資料!D34 -> 4 | E34: =原始資料!E34 -> 3 | F34: =原始資料!F34 -> 4 | G34: =原始資料!G34 -> 3 | H34: =原始資料!H34 -> 4 | ... M34: =原始資料!M34 -> 3 | N34: =STANDARDIZE(B34,AVERAGE(B$5:B$34),STDEV(B$5:B$34)) -> 0.51877624 | O34: =STANDARDIZE(C34,AVERAGE(C$5:C$34),STDEV(C$5:C$34)) -> 0.60589165 | P34: =STANDARDIZE(D34,AVERAGE(D$5:D$34),STDEV(D$5:D$34)) -> 0.66017379 | Q34: =STANDARDIZE(E34,AVERAGE(E$5:E$34),STDEV(E$5:E$34)) -> -0.49159604 | R34: =STANDARDIZE(F34,AVERAGE(F$5:F$34),STDEV(F$5:F$34)) -> 0.78971888 | S34: =STANDARDIZE(G34,AVERAGE(G$5:G$34),STDEV(G$5:G$34)) -> -0.32773069 | T34: =STANDARDIZE(H34,AVERAGE(H$5:H$34),STDEV(H$5:H$34)) -> 0.57845949 | U34: =STANDARDIZE(I34,AVERAGE(I$5:I$34),STDEV(I$5:I$34)) -> 0.72285719 | ... Y34: =STANDARDIZE(M34,AVERAGE(M$5:M$34),STDEV(M$5:M$34)) -> -0.32218493 | Z34: =AVERAGE(N34:P34) -> 0.59494723 | AA34: =AVERAGE(Q34:S34) -> -0.0098692836 | AB34: =AVERAGE(T34:V34) -> 0.67099758 | AC34: =AVERAGE(W34:Y34) -> 0.45828053 | AD34: =STANDARDIZE(Z34,AVERAGE(Z$5:Z$34),STDEV(Z$5:Z$34)) -> 0.67614559 | AE34: =STANDARDIZE(AA34,AVERAGE(AA$5:AA$34),STDEV(AA$5:AA$34)) -> -0.010786881 | AF34: =STANDARDIZE(AB34,AVERAGE(AB$5:AB$34),STDEV(AB$5:AB$34)) -> 0.74888497 | AG34: =STANDARDIZE(AC34,AVERAGE(AC$5:AC$34),STDEV(AC$5:AC$34)) -> 0.50446523
A37: 0-1 外部負荷量 λ
A38: 題項 | B38: ENG1 | C38: ENG2 | D38: ENG3 | E38: TQ1 | F38: TQ2 | G38: TQ3 | H38: SAT1 | I38: SAT2 | J38: SAT3 | K38: INT1 | L38: INT2 | M38: INT3
A39: λ | B39: =CORREL(B$5:B$34,AD$5:AD$34) -> 0.88040547 | C39: =CORREL(C$5:C$34,AD$5:AD$34) -> 0.90939103 | D39: =CORREL(D$5:D$34,AD$5:AD$34) -> 0.84993331 | E39: =CORREL(E$5:E$34,AE$5:AE$34) -> 0.91386287 | F39: =CORREL(F$5:F$34,AE$5:AE$34) -> 0.89675434 | G39: =CORREL(G$5:G$34,AE$5:AE$34) -> 0.9341846 | H39: =CORREL(H$5:H$34,AF$5:AF$34) -> 0.87142406 | I39: =CORREL(I$5:I$34,AF$5:AF$34) -> 0.91337887 | J39: =CORREL(J$5:J$34,AF$5:AF$34) -> 0.90318367 | K39: =CORREL(K$5:K$34,AG$5:AG$34) -> 0.91098959 | L39: =CORREL(L$5:L$34,AG$5:AG$34) -> 0.93185524 | M39: =CORREL(M$5:M$34,AG$5:AG$34) -> 0.88249977
A40: λ² | B40: =B39^2 -> 0.77511379 | C40: =C39^2 -> 0.82699205 | D40: =D39^2 -> 0.72238663 | E40: =E39^2 -> 0.83514535 | F40: =F39^2 -> 0.80416835 | G40: =G39^2 -> 0.87270087 | H40: =H39^2 -> 0.7593799 | I40: =I39^2 -> 0.83426096 | ... M40: =M39^2 -> 0.77880584
A42: 0-2 各構念 AVE 與 CR
A43: 構念 | B43: Σλ | C43: Σλ² | D43: Σ(1−λ²) | E43: AVE | F43: CR
A44: ENG（學習投入） | B44: =SUM(B39:D39) -> 2.6397298 | C44: =SUM(B40:D40) -> 2.3244925 | D44: =3-C44 -> 0.67550753 | E44: =C44/3 -> 0.77483082 | F44: =B44^2/(B44^2+D44) -> 0.91162536
A45: TQ（教學品質） | B45: =SUM(E39:G39) -> 2.7448018 | C45: =SUM(E40:G40) -> 2.5120146 | D45: =3-C45 -> 0.48798543 | E45: =C45/3 -> 0.83733819 | F45: =B45^2/(B45^2+D45) -> 0.93916852
A46: SAT（學習滿意度） | B46: =SUM(H39:J39) -> 2.6879866 | C46: =SUM(H40:J40) -> 2.4093816 | D46: =3-C46 -> 0.59061841 | E46: =C46/3 -> 0.8031272 | F46: =B46^2/(B46^2+D46) -> 0.92443364
A47: INT（持續學習意願） | B47: =SUM(K39:M39) -> 2.7253446 | C47: =SUM(K40:M40) -> 2.4770621 | D47: =3-C47 -> 0.52293795 | E47: =C47/3 -> 0.82568735 | F47: =B47^2/(B47^2+D47) -> 0.93422529

Sheet 2_路徑與R2
A1: 步驟 1–3：共線性 VIF、路徑係數 β、R²
A2: 結構模型：ENG → SAT、TQ → SAT、TQ → INT、SAT → INT。β 以 LINEST 對標準化構念分數做 OLS 迴歸取得。
A4: 步驟 1｜共線性檢查（VIF）
A5: 內生構念 | B5: 預測變數 | C5: 預測變數間 r | D5: VIF = 1/(1−r²) | E5: 判斷（< 3 理想；< 5 可接受）
A6: SAT | B6: ENG、TQ | C6: =CORREL(1_構念分數!AD$5:AD$34,1_構念分數!AE$5:AE$34) -> 0.48863292 | D6: =1/(1-C6^2) -> 1.3136498 | E6: =IF(D6<3,"理想",IF(D6<5,"可接受","共線性過高")) -> 理想
A7: INT | B7: TQ、SAT | C7: =CORREL(1_構念分數!AE$5:AE$34,1_構念分數!AF$5:AF$34) -> 0.65346949 | D7: =1/(1-C7^2) -> 1.7452688 | E7: =IF(D7<3,"理想",IF(D7<5,"可接受","共線性過高")) -> 理想
A9: 步驟 2｜路徑係數 β 與 OLS 顯著性（正式顯著性請見 5_Bootstrap）
A10: 路徑 | B10: β | C10: SE（OLS） | D10: t | E10: df | F10: p | G10: 判斷（α=.05）
A11: ENG → SAT | B11: =INDEX(LINEST(1_構念分數!AF$5:AF$34,1_構念分數!AD$5:AE$34,TRUE(),TRUE()),1,2) -> 0.33502103 | C11: =INDEX(LINEST(1_構念分數!AF$5:AF$34,1_構念分數!AD$5:AE$34,TRUE(),TRUE()),2,2) -> 0.15401453 | D11: =B11/C11 -> 2.175256 | E11: =INDEX(LINEST(1_構念分數!AF$5:AF$34,1_構念分數!AD$5:AE$34,TRUE(),TRUE()),4,2) -> 27 | F11: =TDIST(ABS(D11),E11,2) -> 0.038538847 | G11: =IF(F11<0.05,"顯著","不顯著") -> 顯著
A12: TQ → SAT | B12: =INDEX(LINEST(1_構念分數!AF$5:AF$34,1_構念分數!AD$5:AE$34,TRUE(),TRUE()),1,1) -> 0.48976718 | C12: =INDEX(LINEST(1_構念分數!AF$5:AF$34,1_構念分數!AD$5:AE$34,TRUE(),TRUE()),2,1) -> 0.15401453 | D12: =B12/C12 -> 3.1800062 | E12: =INDEX(LINEST(1_構念分數!AF$5:AF$34,1_構念分數!AD$5:AE$34,TRUE(),TRUE()),4,2) -> 27 | F12: =TDIST(ABS(D12),E12,2) -> 0.0036791237 | G12: =IF(F12<0.05,"顯著","不顯著") -> 顯著
A13: TQ → INT | B13: =INDEX(LINEST(1_構念分數!AG$5:AG$34,1_構念分數!AE$5:AF$34,TRUE(),TRUE()),1,2) -> 0.15538053 | C13: =INDEX(LINEST(1_構念分數!AG$5:AG$34,1_構念分數!AE$5:AF$34,TRUE(),TRUE()),2,2) -> 0.1937474 | D13: =B13/C13 -> 0.80197479 | E13: =INDEX(LINEST(1_構念分數!AG$5:AG$34,1_構念分數!AE$5:AF$34,TRUE(),TRUE()),4,2) -> 27 | F13: =TDIST(ABS(D13),E13,2) -> 0.42956992 | G13: =IF(F13<0.05,"顯著","不顯著") -> 不顯著
A14: SAT → INT | B14: =INDEX(LINEST(1_構念分數!AG$5:AG$34,1_構念分數!AE$5:AF$34,TRUE(),TRUE()),1,1) -> 0.53520369 | C14: =INDEX(LINEST(1_構念分數!AG$5:AG$34,1_構念分數!AE$5:AF$34,TRUE(),TRUE()),2,1) -> 0.1937474 | D14: =B14/C14 -> 2.7623788 | E14: =INDEX(LINEST(1_構念分數!AG$5:AG$34,1_構念分數!AE$5:AF$34,TRUE(),TRUE()),4,2) -> 27 | F14: =TDIST(ABS(D14),E14,2) -> 0.010199445 | G14: =IF(F14<0.05,"顯著","不顯著") -> 顯著
A16: 步驟 3｜判定係數 R²
A17: 內生構念 | B17: R² | C17: 調整後 R² | D17: n | E17: 預測變數數 k | F17: 解釋力（Hair et al., 2019）
A18: SAT（學習滿意度） | B18: =INDEX(LINEST(1_構念分數!AF$5:AF$34,1_構念分數!AD$5:AE$34,TRUE(),TRUE()),3,1) -> 0.51246302 | C18: =1-(1-B18)*(D18-1)/(D18-E18-1) -> 0.47634917 | D18: =COUNT(1_構念分數!AF$5:AF$34) -> 30 | E18: 2 | F18: =IF(B18>=0.75,"高度",IF(B18>=0.5,"中度",IF(B18>=0.25,"低度","極低"))) -> 中度
A19: INT（持續學習意願） | B19: =INDEX(LINEST(1_構念分數!AG$5:AG$34,1_構念分數!AE$5:AF$34,TRUE(),TRUE()),3,1) -> 0.41927145 | C19: =1-(1-B19)*(D19-1)/(D19-E19-1) -> 0.37625452 | D19: =COUNT(1_構念分數!AG$5:AG$34) -> 30 | E19: 2 | F19: =IF(B19>=0.75,"高度",IF(B19>=0.5,"中度",IF(B19>=0.25,"低度","極低"))) -> 低度

Sheet 3_f2
A1: 步驟 4：效果量 f²
A2: f² = (R²_included − R²_excluded) / (1 − R²_included)；R²_excluded = 移除該外生構念後，以剩下的預測變數重新估計之 R²（本例只剩一個預測變數，故用 RSQ）。
A4: 路徑 | B4: 內生構念 | C4: R² included | D4: 移除後保留之預測變數 | E4: R² excluded | F4: ΔR² | G4: f² | H4: 效果大小
A5: ENG → SAT | B5: SAT | C5: =2_路徑與R2!B18 -> 0.51246302 | D5: TQ | E5: =RSQ(1_構念分數!AF$5:AF$34,1_構念分數!AE$5:AE$34) -> 0.42702237 | F5: =C5-E5 -> 0.085440649 | G5: =F5/(1-C5) -> 0.17524957 | H5: =IF(G5>=0.35,"大",IF(G5>=0.15,"中",IF(G5>=0.02,"小","無"))) -> 中
A6: TQ → SAT | B6: SAT | C6: =2_路徑與R2!B18 -> 0.51246302 | D6: ENG | E6: =RSQ(1_構念分數!AF$5:AF$34,1_構念分數!AD$5:AD$34) -> 0.32986345 | F6: =C6-E6 -> 0.18259957 | G6: =F6/(1-C6) -> 0.3745348 | H6: =IF(G6>=0.35,"大",IF(G6>=0.15,"中",IF(G6>=0.02,"小","無"))) -> 大
A7: TQ → INT | B7: INT | C7: =2_路徑與R2!B19 -> 0.41927145 | D7: SAT | E7: =RSQ(1_構念分數!AG$5:AG$34,1_構念分數!AF$5:AF$34) -> 0.40543798 | F7: =C7-E7 -> 0.013833461 | G7: =F7/(1-C7) -> 0.023820873 | H7: =IF(G7>=0.35,"大",IF(G7>=0.15,"中",IF(G7>=0.02,"小","無"))) -> 小
A8: SAT → INT | B8: INT | C8: =2_路徑與R2!B19 -> 0.41927145 | D8: TQ | E8: =RSQ(1_構念分數!AG$5:AG$34,1_構念分數!AE$5:AE$34) -> 0.25514602 | F8: =C8-E8 -> 0.16412543 | G8: =F8/(1-C8) -> 0.28261987 | H8: =IF(G8>=0.35,"大",IF(G8>=0.15,"中",IF(G8>=0.02,"小","無"))) -> 中

Sheet 4_Q2
A1: 步驟 5：預測相關性 Q²（留一交叉驗證 PRESS 法）
A2: 每次留下一位受試者不參與估計，用其餘 29 人的模型去預測他；Q² = 1 − PRESS / SSO。利用 hat 值 h，留一殘差 = e / (1 − h)，不必真的重跑 30 次迴歸。
A4: 內生構念：SAT（預測變數 ENG、TQ） | O4: 內生構念：INT（預測變數 TQ、SAT）
A5: 受試者 | B5: y=SAT | C5: x1=ENG | D5: x2=TQ | E5: dx1=x1−x̄1 | F5: dx2=x2−x̄2 | G5: h（hat 值） | H5: ŷ | I5: e = y − ŷ | J5: e₍₋ᵢ₎ = e/(1−h) | K5: e₍₋ᵢ₎² | L5: (y − ȳ)² | O5: 受試者 | P5: y=INT | Q5: x1=TQ | R5: x2=SAT | S5: dx1=x1−x̄1 | T5: dx2=x2−x̄2 | U5: h（hat 值） | V5: ŷ | W5: e = y − ŷ | X5: e₍₋ᵢ₎ = e/(1−h) | Y5: e₍₋ᵢ₎² | Z5: (y − ȳ)²
A6: =1_構念分數!A5 -> R01 | B6: =1_構念分數!AF5 -> 0.34550282 | C6: =1_構念分數!AD5 -> 0.67614559 | D6: =1_構念分數!AE5 -> 0.43696497 | E6: =C6-$B$39 -> 0.67614559 | F6: =D6-$B$40 -> 0.43696497 | G6: =1/$B$38+($B$42*E6^2-2*$B$43*E6*F6+$B$41*F6^2)/$B$44 -> 0.049612452 | H6: =$B$45+$B$46*C6+$B$47*D6 -> 0.4405341 | I6: =B6-H6 -> -0.095031273 | J6: =I6/(1-G6) -> -0.099992128 | K6: =J6^2 -> 0.0099984256 | L6: =(B6-AVERAGE(B$6:B$35))^2 -> 0.1193722 | O6: =1_構念分數!A5 -> R01 | P6: =1_構念分數!AG5 -> -0.2741407 | Q6: =1_構念分數!AE5 -> 0.43696497 | R6: =1_構念分數!AF5 -> 0.34550282 | S6: =Q6-$P$39 -> 0.43696497 | T6: =R6-$P$40 -> 0.34550282 | U6: =1/$P$38+($P$42*S6^2-2*$P$43*S6*T6+$P$41*T6^2)/$P$44 -> 0.040133778 | V6: =$P$45+$P$46*Q6+$P$47*R6 -> 0.25281023 | W6: =P6-V6 -> -0.52695094 | X6: =W6/(1-U6) -> -0.54898373 | Y6: =X6^2 -> 0.30138313 | Z6: =(P6-AVERAGE(P$6:P$35))^2 -> 0.075153125
A7: =1_構念分數!A6 -> R02 | B7: =1_構念分數!AF6 -> -0.43121169 | C7: =1_構念分數!AD6 -> 0.29130645 | D7: =1_構念分數!AE6 -> 0.83496662 | E7: =C7-$B$39 -> 0.29130645 | F7: =D7-$B$40 -> 0.83496662 | G7: =1/$B$38+($B$42*E7^2-2*$B$43*E7*F7+$B$41*F7^2)/$B$44 -> 0.057990414 | H7: =$B$45+$B$46*C7+$B$47*D7 -> 0.50653304 | I7: =B7-H7 -> -0.93774473 | J7: =I7/(1-G7) -> -0.99547259 | K7: =J7^2 -> 0.99096568 | L7: =(B7-AVERAGE(B$6:B$35))^2 -> 0.18594352 | O7: =1_構念分數!A6 -> R02 | P7: =1_構念分數!AG6 -> -0.2741407 | Q7: =1_構念分數!AE6 -> 0.83496662 | R7: =1_構念分數!AF6 -> -0.43121169 | S7: =Q7-$P$39 -> 0.83496662 | T7: =R7-$P$40 -> -0.43121169 | U7: =1/$P$38+($P$42*S7^2-2*$P$43*S7*T7+$P$41*T7^2)/$P$44 -> 0.11479964 | V7: =$P$45+$P$46*Q7+$P$47*R7 -> -0.10104853 | W7: =P7-V7 -> -0.17309217 | X7: =W7/(1-U7) -> -0.1955401 | Y7: =X7^2 -> 0.038235931 | Z7: =(P7-AVERAGE(P$6:P$35))^2 -> 0.075153125
A8: =1_構念分數!A7 -> R03 | B8: =1_構念分數!AF7 -> 0.34550282 | C8: =1_構念分數!AD7 -> -0.18631993 | D8: =1_構念分數!AE7 -> -1.7196834 | E8: =C8-$B$39 -> -0.18631993 | F8: =D8-$B$40 -> -1.7196834 | G8: =1/$B$38+($B$42*E8^2-2*$B$43*E8*F8+$B$41*F8^2)/$B$44 -> 0.15468284 | H8: =$B$45+$B$46*C8+$B$47*D8 -> -0.90466561 | I8: =B8-H8 -> 1.2501684 | J8: =I8/(1-G8) -> 1.4789342 | K8: =J8^2 -> 2.1872463 | L8: =(B8-AVERAGE(B$6:B$35))^2 -> 0.1193722 | O8: =1_構念分數!A7 -> R03 | P8: =1_構念分數!AG7 -> 0.1181842 | Q8: =1_構念分數!AE7 -> -1.7196834 | R8: =1_構念分數!AF7 -> 0.34550282 | S8: =Q8-$P$39 -> -1.7196834 | T8: =R8-$P$40 -> 0.34550282 | U8: =1/$P$38+($P$42*S8^2-2*$P$43*S8*T8+$P$41*T8^2)/$P$44 -> 0.2652259 | V8: =$P$45+$P$46*Q8+$P$47*R8 -> -0.082290934 | W8: =P8-V8 -> 0.20047513 | X8: =W8/(1-U8) -> 0.27283914 | Y8: =X8^2 -> 0.074441196 | Z8: =(P8-AVERAGE(P$6:P$35))^2 -> 0.013967505
A9: =1_構念分數!A8 -> R04 | B9: =1_構念分數!AF8 -> 0.74888497 | C9: =1_構念分數!AD8 -> -0.15003136 | D9: =1_構念分數!AE8 -> 0.38721477 | E9: =C9-$B$39 -> -0.15003136 | F9: =D9-$B$40 -> 0.38721477 | G9: =1/$B$38+($B$42*E9^2-2*$B$43*E9*F9+$B$41*F9^2)/$B$44 -> 0.043716526 | H9: =$B$45+$B$46*C9+$B$47*D9 -> 0.13938142 | I9: =B9-H9 -> 0.60950354 | J9: =I9/(1-G9) -> 0.63736701 | K9: =J9^2 -> 0.40623671 | L9: =(B9-AVERAGE(B$6:B$35))^2 -> 0.56082869 | O9: =1_構念分數!A8 -> R04 | P9: =1_構念分數!AG8 -> 0.169177 | Q9: =1_構念分數!AE8 -> 0.38721477 | R9: =1_構念分數!AF8 -> 0.74888497 | S9: =Q9-$P$39 -> 0.38721477 | T9: =R9-$P$40 -> 0.74888497 | U9: =1/$P$38+($P$42*S9^2-2*$P$43*S9*T9+$P$41*T9^2)/$P$44 -> 0.053300334 | V9: =$P$45+$P$46*Q9+$P$47*R9 -> 0.46097163 | W9: =P9-V9 -> -0.29179463 | X9: =W9/(1-U9) -> -0.30822302 | Y9: =X9^2 -> 0.095001431 | Z9: =(P9-AVERAGE(P$6:P$35))^2 -> 0.028620858
A10: =1_構念分數!A9 -> R05 | B10: =1_構念分數!AF9 -> -0.43121169 | C10: =1_構念分數!AD9 -> -1.0124969 | D10: =1_構念分數!AE9 -> 0.83496662 | E10: =C10-$B$39 -> -1.0124969 | F10: =D10-$B$40 -> 0.83496662 | G10: =1/$B$38+($B$42*E10^2-2*$B$43*E10*F10+$B$41*F10^2)/$B$44 -> 0.14877601 | H10: =$B$45+$B$46*C10+$B$47*D10 -> 0.069731496 | I10: =B10-H10 -> -0.50094319 | J10: =I10/(1-G10) -> -0.5884975 | K10: =J10^2 -> 0.3463293 | L10: =(B10-AVERAGE(B$6:B$35))^2 -> 0.18594352 | O10: =1_構念分數!A9 -> R05 | P10: =1_構念分數!AG9 -> -1.0527466 | Q10: =1_構念分數!AE9 -> 0.83496662 | R10: =1_構念分數!AF9 -> -0.43121169 | S10: =Q10-$P$39 -> 0.83496662 | T10: =R10-$P$40 -> -0.43121169 | U10: =1/$P$38+($P$42*S10^2-2*$P$43*S10*T10+$P$41*T10^2)/$P$44 -> 0.11479964 | V10: =$P$45+$P$46*Q10+$P$47*R10 -> -0.10104853 | W10: =P10-V10 -> -0.9516981 | X10: =W10/(1-U10) -> -1.0751217 | Y10: =X10^2 -> 1.1558866 | Z10: =(P10-AVERAGE(P$6:P$35))^2 -> 1.1082755
A11: =1_構念分數!A10 -> R06 | B11: =1_構念分數!AF10 -> -0.78988132 | C11: =1_構念分數!AD10 -> -1.4175461 | D11: =1_構念分數!AE10 -> -0.44235841 | E11: =C11-$B$39 -> -1.4175461 | F11: =D11-$B$40 -> -0.44235841 | G11: =1/$B$38+($B$42*E11^2-2*$B$43*E11*F11+$B$41*F11^2)/$B$44 -> 0.10546223 | H11: =$B$45+$B$46*C11+$B$47*D11 -> -0.6915604 | I11: =B11-H11 -> -0.09832092 | J11: =I11/(1-G11) -> -0.10991254 | K11: =J11^2 -> 0.012080767 | L11: =(B11-AVERAGE(B$6:B$35))^2 -> 0.6239125 | O11: =1_構念分數!A10 -> R06 | P11: =1_構念分數!AG10 -> -0.71745841 | Q11: =1_構念分數!AE10 -> -0.44235841 | R11: =1_構念分數!AF10 -> -0.78988132 | S11: =Q11-$P$39 -> -0.44235841 | T11: =R11-$P$40 -> -0.78988132 | U11: =1/$P$38+($P$42*S11^2-2*$P$43*S11*T11+$P$41*T11^2)/$P$44 -> 0.055175377 | V11: =$P$45+$P$46*Q11+$P$47*R11 -> -0.49148128 | W11: =P11-V11 -> -0.22597713 | X11: =W11/(1-U11) -> -0.23917362 | Y11: =X11^2 -> 0.05720402 | Z11: =(P11-AVERAGE(P$6:P$35))^2 -> 0.51474656
A12: =1_構念分數!A11 -> R07 | B12: =1_構念分數!AF11 -> -1.2079262 | C12: =1_構念分數!AD11 -> 0.23480778 | D12: =1_構念分數!AE11 -> -0.89011027 | E12: =C12-$B$39 -> 0.23480778 | F12: =D12-$B$40 -> -0.89011027 | G12: =1/$B$38+($B$42*E12^2-2*$B$43*E12*F12+$B$41*F12^2)/$B$44 -> 0.08097281 | H12: =$B$45+$B$46*C12+$B$47*D12 -> -0.35728125 | I12: =B12-H12 -> -0.85064496 | J12: =I12/(1-G12) -> -0.92559281 | K12: =J12^2 -> 0.85672205 | L12: =(B12-AVERAGE(B$6:B$35))^2 -> 1.4590857 | O12: =1_構念分數!A11 -> R07 | P12: =1_構念分數!AG11 -> -0.6664656 | Q12: =1_構念分數!AE11 -> -0.89011027 | R12: =1_構念分數!AF11 -> -1.2079262 | S12: =Q12-$P$39 -> -0.89011027 | T12: =R12-$P$40 -> -1.2079262 | U12: =1/$P$38+($P$42*S12^2-2*$P$43*S12*T12+$P$41*T12^2)/$P$44 -> 0.084257722 | V12: =$P$45+$P$46*Q12+$P$47*R12 -> -0.78479237 | W12: =P12-V12 -> 0.11832676 | X12: =W12/(1-U12) -> 0.12921404 | Y12: =X12^2 -> 0.016696268 | Z12: =(P12-AVERAGE(P$6:P$35))^2 -> 0.4441764
A13: =1_構念分數!A12 -> R08 | B13: =1_構念分數!AF12 -> 0.68950971 | C13: =1_構念分數!AD12 -> -0.59136917 | D13: =1_構念分數!AE12 -> 0.40339509 | E13: =C13-$B$39 -> -0.59136917 | F13: =D13-$B$40 -> 0.40339509 | G13: =1/$B$38+($B$42*E13^2-2*$B$43*E13*F13+$B$41*F13^2)/$B$44 -> 0.067106688 | H13: =$B$45+$B$46*C13+$B$47*D13 -> -0.00055143515 | I13: =B13-H13 -> 0.69006114 | J13: =I13/(1-G13) -> 0.73969996 | K13: =J13^2 -> 0.54715603 | L13: =(B13-AVERAGE(B$6:B$35))^2 -> 0.47542364 | O13: =1_構念分數!A12 -> R08 | P13: =1_構念分數!AG12 -> -1.0527466 | Q13: =1_構念分數!AE12 -> 0.40339509 | R13: =1_構念分數!AF12 -> 0.68950971 | S13: =Q13-$P$39 -> 0.40339509 | T13: =R13-$P$40 -> 0.68950971 | U13: =1/$P$38+($P$42*S13^2-2*$P$43*S13*T13+$P$41*T13^2)/$P$44 -> 0.049861205 | V13: =$P$45+$P$46*Q13+$P$47*R13 -> 0.43170788 | W13: =P13-V13 -> -1.4844545 | X13: =W13/(1-U13) -> -1.5623554 | Y13: =X13^2 -> 2.4409545 | Z13: =(P13-AVERAGE(P$6:P$35))^2 -> 1.1082755
A14: =1_構念分數!A13 -> R09 | B14: =1_構念分數!AF13 -> 0.74888497 | C14: =1_構念分數!AD13 -> 0.23480778 | D14: =1_構念分數!AE13 -> 0.83496662 | E14: =C14-$B$39 -> 0.23480778 | F14: =D14-$B$40 -> 0.83496662 | G14: =1/$B$38+($B$42*E14^2-2*$B$43*E14*F14+$B$41*F14^2)/$B$44 -> 0.058732276 | H14: =$B$45+$B$46*C14+$B$47*D14 -> 0.48760479 | I14: =B14-H14 -> 0.26128017 | J14: =I14/(1-G14) -> 0.27758327 | K14: =J14^2 -> 0.077052472 | L14: =(B14-AVERAGE(B$6:B$35))^2 -> 0.56082869 | O14: =1_構念分數!A13 -> R09 | P14: =1_構念分數!AG13 -> 0.50446523 | Q14: =1_構念分數!AE13 -> 0.83496662 | R14: =1_構念分數!AF13 -> 0.74888497 | S14: =Q14-$P$39 -> 0.83496662 | T14: =R14-$P$40 -> 0.74888497 | U14: =1/$P$38+($P$42*S14^2-2*$P$43*S14*T14+$P$41*T14^2)/$P$44 -> 0.05986003 | V14: =$P$45+$P$46*Q14+$P$47*R14 -> 0.53054355 | W14: =P14-V14 -> -0.026078325 | X14: =W14/(1-U14) -> -0.027738769 | Y14: =X14^2 -> 0.0007694393 | Z14: =(P14-AVERAGE(P$6:P$35))^2 -> 0.25448516
A15: =1_構念分數!A14 -> R10 | B15: =1_構念分數!AF14 -> 0.39021534 | C15: =1_構念分數!AD14 -> -1.4377562 | D15: =1_構念分數!AE14 -> -0.010786881 | E15: =C15-$B$39 -> -1.4377562 | F15: =D15-$B$40 -> -0.010786881 | G15: =1/$B$38+($B$42*E15^2-2*$B$43*E15*F15+$B$41*F15^2)/$B$44 -> 0.12629005 | H15: =$B$45+$B$46*C15+$B$47*D15 -> -0.48696163 | I15: =B15-H15 -> 0.87717697 | J15: =I15/(1-G15) -> 1.0039682 | K15: =J15^2 -> 1.0079521 | L15: =(B15-AVERAGE(B$6:B$35))^2 -> 0.15226801 | O15: =1_構念分數!A14 -> R10 | P15: =1_構念分數!AG14 -> -0.2741407 | Q15: =1_構念分數!AE14 -> -0.010786881 | R15: =1_構念分數!AF14 -> 0.39021534 | S15: =Q15-$P$39 -> -0.010786881 | T15: =R15-$P$40 -> 0.39021534 | U15: =1/$P$38+($P$42*S15^2-2*$P$43*S15*T15+$P$41*T15^2)/$P$44 -> 0.042835151 | V15: =$P$45+$P$46*Q15+$P$47*R15 -> 0.20716862 | W15: =P15-V15 -> -0.48130932 | X15: =W15/(1-U15) -> -0.50284893 | Y15: =X15^2 -> 0.25285705 | Z15: =(P15-AVERAGE(P$6:P$35))^2 -> 0.075153125
A16: =1_構念分數!A15 -> R11 | B16: =1_構念分數!AF15 -> 1.5255995 | C16: =1_構念分數!AD15 -> 1.5023225 | D16: =1_構念分數!AE15 -> -0.44235841 | E16: =C16-$B$39 -> 1.5023225 | F16: =D16-$B$40 -> -0.44235841 | G16: =1/$B$38+($B$42*E16^2-2*$B$43*E16*F16+$B$41*F16^2)/$B$44 -> 0.17385358 | H16: =$B$45+$B$46*C16+$B$47*D16 -> 0.28665702 | I16: =B16-H16 -> 1.2389425 | J16: =I16/(1-G16) -> 1.4996645 | K16: =J16^2 -> 2.2489936 | L16: =(B16-AVERAGE(B$6:B$35))^2 -> 2.3274538 | O16: =1_構念分數!A15 -> R11 | P16: =1_構念分數!AG15 -> 0.94778293 | Q16: =1_構念分數!AE15 -> -0.44235841 | R16: =1_構念分數!AF15 -> 1.5255995 | S16: =Q16-$P$39 -> -0.44235841 | T16: =R16-$P$40 -> 1.5255995 | U16: =1/$P$38+($P$42*S16^2-2*$P$43*S16*T16+$P$41*T16^2)/$P$44 -> 0.23826026 | V16: =$P$45+$P$46*Q16+$P$47*R16 -> 0.74777259 | W16: =P16-V16 -> 0.20001034 | X16: =W16/(1-U16) -> 0.26257044 | Y16: =X16^2 -> 0.068943237 | Z16: =(P16-AVERAGE(P$6:P$35))^2 -> 0.89829248
A17: =1_構念分數!A16 -> R12 | B17: =1_構念分數!AF16 -> -0.072542062 | C17: =1_構念分數!AD16 -> -1.4538347 | D17: =1_構念分數!AE16 -> -0.44235841 | E17: =C17-$B$39 -> -1.4538347 | F17: =D17-$B$40 -> -0.44235841 | G17: =1/$B$38+($B$42*E17^2-2*$B$43*E17*F17+$B$41*F17^2)/$B$44 -> 0.10947162 | H17: =$B$45+$B$46*C17+$B$47*D17 -> -0.70371783 | I17: =B17-H17 -> 0.63117577 | J17: =I17/(1-G17) -> 0.70876547 | K17: =J17^2 -> 0.50234849 | L17: =(B17-AVERAGE(B$6:B$35))^2 -> 0.0052623508 | O17: =1_構念分數!A16 -> R12 | P17: =1_構念分數!AG16 -> 0.94778293 | Q17: =1_構念分數!AE16 -> -0.44235841 | R17: =1_構念分數!AF16 -> -0.072542062 | S17: =Q17-$P$39 -> -0.44235841 | T17: =R17-$P$40 -> -0.072542062 | U17: =1/$P$38+($P$42*S17^2-2*$P$43*S17*T17+$P$41*T17^2)/$P$44 -> 0.042902473 | V17: =$P$45+$P$46*Q17+$P$47*R17 -> -0.10755866 | W17: =P17-V17 -> 1.0553416 | X17: =W17/(1-U17) -> 1.1026479 | Y17: =X17^2 -> 1.2158324 | Z17: =(P17-AVERAGE(P$6:P$35))^2 -> 0.89829248
... A35: =1_構念分數!A34 -> R30 | B35: =1_構念分數!AF34 -> 0.74888497 | C35: =1_構念分數!AD34 -> 0.67614559 | D35: =1_構念分數!AE34 -> -0.010786881 | E35: =C35-$B$39 -> 0.67614559 | F35: =D35-$B$40 -> -0.010786881 | G35: =1/$B$38+($B$42*E35^2-2*$B$43*E35*F35+$B$41*F35^2)/$B$44 -> 0.054370616 | H35: =$B$45+$B$46*C35+$B$47*D35 -> 0.22123994 | I35: =B35-H35 -> 0.52764503 | J35: =I35/(1-G35) -> 0.55798291 | K35: =J35^2 -> 0.31134492 | L35: =(B35-AVERAGE(B$6:B$35))^2 -> 0.56082869 | O35: =1_構念分數!A34 -> R30 | P35: =1_構念分數!AG34 -> 0.50446523 | Q35: =1_構念分數!AE34 -> -0.010786881 | R35: =1_構念分數!AF34 -> 0.74888497 | S35: =Q35-$P$39 -> -0.010786881 | T35: =R35-$P$40 -> 0.74888497 | U35: =1/$P$38+($P$42*S35^2-2*$P$43*S35*T35+$P$41*T35^2)/$P$44 -> 0.067727327 | V35: =$P$45+$P$46*Q35+$P$47*R35 -> 0.39912993 | W35: =P35-V35 -> 0.1053353 | X35: =W35/(1-U35) -> 0.11298765 | Y35: =X35^2 -> 0.012766209 | Z35: =(P35-AVERAGE(P$6:P$35))^2 -> 0.25448516
A37: 參數計算 | O37: 參數計算
A38: n | B38: =COUNT(B6:B35) -> 30 | O38: n | P38: =COUNT(P6:P35) -> 30
A39: x̄1 | B39: =AVERAGE(C6:C35) -> 0 | O39: x̄1 | P39: =AVERAGE(Q6:Q35) -> 1.994932e-17
A40: x̄2 | B40: =AVERAGE(D6:D35) -> 1.994932e-17 | O40: x̄2 | P40: =AVERAGE(R6:R35) -> 0
A41: S11 = Σdx1² | B41: =SUMSQ(E6:E35) -> 29 | O41: S11 = Σdx1² | P41: =SUMSQ(S6:S35) -> 29
A42: S22 = Σdx2² | B42: =SUMSQ(F6:F35) -> 29 | O42: S22 = Σdx2² | P42: =SUMSQ(T6:T35) -> 29
A43: S12 = Σdx1·dx2 | B43: =SUMPRODUCT(E6:E35,F6:F35) -> 14.170355 | O43: S12 = Σdx1·dx2 | P43: =SUMPRODUCT(S6:S35,T6:T35) -> 18.950615
A44: det = S11·S22 − S12² | B44: =$B$41*$B$42-$B$43^2 -> 640.20105 | O44: det = S11·S22 − S12² | P44: =$P$41*$P$42-$P$43^2 -> 481.87419
A45: 截距 b0 | B45: =INDEX(LINEST(1_構念分數!AF$5:AF$34,1_構念分數!AD$5:AE$34,TRUE(),TRUE()),1,3) -> -9.7705222e-18 | O45: 截距 b0 | P45: =INDEX(LINEST(1_構念分數!AG$5:AG$34,1_構念分數!AE$5:AF$34,TRUE(),TRUE()),1,3) -> -3.0997359e-18
A46: b1（ENG） | B46: =INDEX(LINEST(1_構念分數!AF$5:AF$34,1_構念分數!AD$5:AE$34,TRUE(),TRUE()),1,2) -> 0.33502103 | O46: b1（TQ） | P46: =INDEX(LINEST(1_構念分數!AG$5:AG$34,1_構念分數!AE$5:AF$34,TRUE(),TRUE()),1,2) -> 0.15538053
A47: b2（TQ） | B47: =INDEX(LINEST(1_構念分數!AF$5:AF$34,1_構念分數!AD$5:AE$34,TRUE(),TRUE()),1,1) -> 0.48976718 | O47: b2（SAT） | P47: =INDEX(LINEST(1_構念分數!AG$5:AG$34,1_構念分數!AE$5:AF$34,TRUE(),TRUE()),1,1) -> 0.53520369
A48: PRESS = Σe₍₋ᵢ₎² | B48: =SUM(K6:K35) -> 17.50636 | O48: PRESS = Σe₍₋ᵢ₎² | P48: =SUM(Y6:Y35) -> 20.925255
A49: SSO = Σ(y − ȳ)² | B49: =SUM(L6:L35) -> 29 | O49: SSO = Σ(y − ȳ)² | P49: =SUM(Z6:Z35) -> 29
A50: Q² = 1 − PRESS/SSO | B50: =1-$B$48/$B$49 -> 0.3963324 | O50: Q² = 1 − PRESS/SSO | P50: =1-$P$48/$P$49 -> 0.2784395
A51: 判斷 | B51: =IF(B50>0,"具預測相關性","不具預測相關性") -> 具預測相關性 | O51: 判斷 | P51: =IF(P50>0,"具預測相關性","不具預測相關性") -> 具預測相關性
A52: 對照：R² | B52: =2_路徑與R2!B18 -> 0.51246302 | O52: 對照：R² | P52: =2_路徑與R2!B19 -> 0.41927145

Sheet Boot_抽樣次數
A1: Bootstrap 抽樣次數：500 次重抽，每次從 30 人中「抽出放回」抽 30 人；數字 = 該受試者在該次樣本中被抽到幾次（固定亂數種子 2026 產生，藍字輸入值）
A4: 受試者 | B4: 1 | C4: 2 | D4: 3 | E4: 4 | F4: 5 | G4: 6 | H4: 7 | I4: 8 | J4: 9 | K4: 10 | L4: 11 | M4: 12 | N4: 13 | O4: 14 | P4: 15 | Q4: 16 | R4: 17 | S4: 18 | T4: 19 | U4: 20 | V4: 21 | W4: 22 | X4: 23 | Y4: 24 | Z4: 25 | AA4: 26 | AB4: 27 | AC4: 28 | AD4: 29 | AE4: 30 | AF4: 31 | AG4: 32 | AH4: 33 | AI4: 34 | AJ4: 35 | AK4: 36 | AL4: 37 | AM4: 38 | AN4: 39 | AO4: 40 | AP4: 41 | AQ4: 42 | AR4: 43 | AS4: 44 | AT4: 45 | AU4: 46 | AV4: 47 | AW4: 48 | AX4: 49 | AY4: 50 | AZ4: 51 | BA4: 52 | BB4: 53 | BC4: 54 | BD4: 55 | BE4: 56 | BF4: 57 | BG4: 58 | BH4: 59 | BI4: 60 | BJ4: 61 | BK4: 62 | BL4: 63 | BM4: 64 | BN4: 65 | BO4: 66 | BP4: 67 | BQ4: 68 | BR4: 69 | BS4: 70 | BT4: 71 | BU4: 72 | BV4: 73 | BW4: 74 | BX4: 75 | BY4: 76 | BZ4: 77 | CA4: 78 | CB4: 79 | CC4: 80 | CD4: 81 | CE4: 82 | CF4: 83 | CG4: 84 | CH4: 85 | CI4: 86 | CJ4: 87 | CK4: 88 | CL4: 89 | CM4: 90 | CN4: 91 | CO4: 92 | CP4: 93 | CQ4: 94 | CR4: 95 | CS4: 96 | CT4: 97 | CU4: 98 | CV4: 99 | CW4: 100 | CX4: 101 | CY4: 102 | CZ4: 103 | DA4: 104 | DB4: 105 | DC4: 106 | DD4: 107 | DE4: 108 | DF4: 109 | DG4: 110 | DH4: 111 | DI4: 112 | DJ4: 113 | DK4: 114 | DL4: 115 | DM4: 116 | DN4: 117 | DO4: 118 | DP4: 119 | DQ4: 120 | DR4: 121 | DS4: 122 | DT4: 123 | DU4: 124 | DV4: 125 | DW4: 126 | DX4: 127 | DY4: 128 | DZ4: 129 | EA4: 130 | EB4: 131 | EC4: 132 | ED4: 133 | EE4: 134 | EF4: 135 | EG4: 136 | EH4: 137 | EI4: 138 | EJ4: 139 | EK4: 140 | EL4: 141 | EM4: 142 | EN4: 143 | EO4: 144 | EP4: 145 | EQ4: 146 | ER4: 147 | ES4: 148 | ET4: 149 | EU4: 150 | EV4: 151 | EW4: 152 | EX4: 153 | EY4: 154 | EZ4: 155 | FA4: 156 | FB4: 157 | FC4: 158 | FD4: 159 | FE4: 160 | FF4: 161 | FG4: 162 | FH4: 163 | FI4: 164 | FJ4: 165 | FK4: 166 | FL4: 167 | FM4: 168 | FN4: 169 | FO4: 170 | FP4: 171 | FQ4: 172 | FR4: 173 | FS4: 174 | FT4: 175 | FU4: 176 | FV4: 177 | FW4: 178 | FX4: 179 | FY4: 180 | FZ4: 181 | GA4: 182 | GB4: 183 | GC4: 184 | GD4: 185 | GE4: 186 | GF4: 187 | GG4: 188 | GH4: 189 | GI4: 190 | GJ4: 191 | GK4: 192 | GL4: 193 | GM4: 194 | GN4: 195 | GO4: 196 | GP4: 197 | GQ4: 198 | GR4: 199 | GS4: 200 | GT4: 201 | GU4: 202 | GV4: 203 | GW4: 204 | GX4: 205 | GY4: 206 | GZ4: 207 | HA4: 208 | HB4: 209 | HC4: 210 | HD4: 211 | HE4: 212 | HF4: 213 | HG4: 214 | HH4: 215 | HI4: 216 | HJ4: 217 | HK4: 218 | HL4: 219 | HM4: 220 | HN4: 221 | HO4: 222 | HP4: 223 | HQ4: 224 | HR4: 225 | HS4: 226 | HT4: 227 | HU4: 228 | HV4: 229 | HW4: 230 | HX4: 231 | HY4: 232 | HZ4: 233 | IA4: 234 | IB4: 235 | IC4: 236 | ID4: 237 | IE4: 238 | IF4: 239 | IG4: 240 | IH4: 241 | II4: 242 | IJ4: 243 | IK4: 244 | IL4: 245 | IM4: 246 | IN4: 247 | IO4: 248 | IP4: 249 | IQ4: 250 | IR4: 251 | IS4: 252 | IT4: 253 | IU4: 254 | IV4: 255 | IW4: 256 | IX4: 257 | IY4: 258 | IZ4: 259 | JA4: 260 | JB4: 261 | JC4: 262 | JD4: 263 | JE4: 264 | JF4: 265 | JG4: 266 | JH4: 267 | JI4: 268 | JJ4: 269 | JK4: 270 | JL4: 271 | JM4: 272 | JN4: 273 | JO4: 274 | JP4: 275 | JQ4: 276 | JR4: 277 | JS4: 278 | JT4: 279 | JU4: 280 | JV4: 281 | JW4: 282 | JX4: 283 | JY4: 284 | JZ4: 285 | KA4: 286 | KB4: 287 | KC4: 288 | KD4: 289 | KE4: 290 | KF4: 291 | KG4: 292 | KH4: 293 | KI4: 294 | KJ4: 295 | KK4: 296 | KL4: 297 | KM4: 298 | KN4: 299 | KO4: 300 | KP4: 301 | KQ4: 302 | KR4: 303 | KS4: 304 | KT4: 305 | KU4: 306 | KV4: 307 | KW4: 308 | KX4: 309 | KY4: 310 | KZ4: 311 | LA4: 312 | LB4: 313 | LC4: 314 | LD4: 315 | LE4: 316 | LF4: 317 | LG4: 318 | LH4: 319 | LI4: 320 | LJ4: 321 | LK4: 322 | LL4: 323 | LM4: 324 | LN4: 325 | LO4: 326 | LP4: 327 | LQ4: 328 | LR4: 329 | LS4: 330 | LT4: 331 | LU4: 332 | LV4: 333 | LW4: 334 | LX4: 335 | LY4: 336 | LZ4: 337 | MA4: 338 | MB4: 339 | MC4: 340 | MD4: 341 | ME4: 342 | MF4: 343 | MG4: 344 | MH4: 345 | MI4: 346 | MJ4: 347 | MK4: 348 | ML4: 349 | MM4: 350 | MN4: 351 | MO4: 352 | MP4: 353 | MQ4: 354 | MR4: 355 | MS4: 356 | MT4: 357 | MU4: 358 | MV4: 359 | MW4: 360 | MX4: 361 | MY4: 362 | MZ4: 363 | NA4: 364 | NB4: 365 | NC4: 366 | ND4: 367 | NE4: 368 | NF4: 369 | NG4: 370 | NH4: 371 | NI4: 372 | NJ4: 373 | NK4: 374 | NL4: 375 | NM4: 376 | NN4: 377 | NO4: 378 | NP4: 379 | NQ4: 380 | NR4: 381 | NS4: 382 | NT4: 383 | NU4: 384 | NV4: 385 | NW4: 386 | NX4: 387 | NY4: 388 | NZ4: 389 | OA4: 390 | OB4: 391 | OC4: 392 | OD4: 393 | OE4: 394 | OF4: 395 | OG4: 396 | OH4: 397 | OI4: 398 | OJ4: 399 | OK4: 400 | OL4: 401 | OM4: 402 | ON4: 403 | OO4: 404 | OP4: 405 | OQ4: 406 | OR4: 407 | OS4: 408 | OT4: 409 | OU4: 410 | OV4: 411 | OW4: 412 | OX4: 413 | OY4: 414 | OZ4: 415 | PA4: 416 | PB4: 417 | PC4: 418 | PD4: 419 | PE4: 420 | PF4: 421 | PG4: 422 | PH4: 423 | PI4: 424 | PJ4: 425 | PK4: 426 | PL4: 427 | PM4: 428 | PN4: 429 | PO4: 430 | PP4: 431 | PQ4: 432 | PR4: 433 | PS4: 434 | PT4: 435 | PU4: 436 | PV4: 437 | PW4: 438 | PX4: 439 | PY4: 440 | PZ4: 441 | QA4: 442 | QB4: 443 | QC4: 444 | QD4: 445 | QE4: 446 | QF4: 447 | QG4: 448 | QH4: 449 | QI4: 450 | QJ4: 451 | QK4: 452 | QL4: 453 | QM4: 454 | QN4: 455 | QO4: 456 | QP4: 457 | QQ4: 458 | QR4: 459 | QS4: 460 | QT4: 461 | QU4: 462 | QV4: 463 | QW4: 464 | QX4: 465 | QY4: 466 | QZ4: 467 | RA4: 468 | RB4: 469 | RC4: 470 | RD4: 471 | RE4: 472 | RF4: 473 | RG4: 474 | RH4: 475 | RI4: 476 | RJ4: 477 | RK4: 478 | RL4: 479 | RM4: 480 | RN4: 481 | RO4: 482 | RP4: 483 | RQ4: 484 | RR4: 485 | RS4: 486 | RT4: 487 | RU4: 488 | RV4: 489 | RW4: 490 | RX4: 491 | RY4: 492 | RZ4: 493 | SA4: 494 | SB4: 495 | SC4: 496 | SD4: 497 | SE4: 498 | SF4: 499 | SG4: 500
A5: R01 | B5: 0 | C5: 0 | D5: 0 | E5: 1 | F5: 0 | G5: 0 | H5: 3 | I5: 2 | J5: 2 | K5: 1 | L5: 4 | M5: 1 | N5: 0 | O5: 0 | P5: 0 | Q5: 2 | R5: 0 | S5: 1 | T5: 1 | U5: 1 | V5: 1 | W5: 2 | X5: 0 | Y5: 2 | Z5: 2 | AA5: 1 | AB5: 1 | AC5: 1 | AD5: 1 | AE5: 0 | AF5: 0 | AG5: 1 | AH5: 0 | AI5: 0 | AJ5: 1 | AK5: 1 | AL5: 0 | AM5: 2 | AN5: 3 | AO5: 1 | AP5: 0 | AQ5: 1 | AR5: 0 | AS5: 0 | AT5: 0 | AU5: 0 | AV5: 1 | AW5: 0 | AX5: 1 | AY5: 0 | AZ5: 0 | BA5: 1 | BB5: 2 | BC5: 0 | BD5: 0 | BE5: 0 | BF5: 0 | BG5: 1 | BH5: 1 | BI5: 0 | BJ5: 0 | BK5: 1 | BL5: 0 | BM5: 3 | BN5: 0 | BO5: 1 | BP5: 1 | BQ5: 1 | BR5: 0 | BS5: 0 | BT5: 1 | BU5: 1 | BV5: 3 | BW5: 4 | BX5: 2 | BY5: 0 | BZ5: 0 | CA5: 2 | CB5: 2 | CC5: 1 | CD5: 2 | CE5: 0 | CF5: 4 | CG5: 0 | CH5: 0 | CI5: 2 | CJ5: 1 | CK5: 0 | CL5: 0 | CM5: 1 | CN5: 3 | CO5: 1 | CP5: 0 | CQ5: 0 | CR5: 1 | CS5: 2 | CT5: 2 | CU5: 0 | CV5: 1 | CW5: 1 | CX5: 4 | CY5: 0 | CZ5: 0 | DA5: 1 | DB5: 1 | DC5: 1 | DD5: 1 | DE5: 0 | DF5: 2 | DG5: 0 | DH5: 1 | DI5: 3 | DJ5: 0 | DK5: 1 | DL5: 1 | DM5: 1 | DN5: 1 | DO5: 2 | DP5: 1 | DQ5: 3 | DR5: 2 | DS5: 0 | DT5: 0 | DU5: 1 | DV5: 2 | DW5: 1 | DX5: 1 | DY5: 2 | DZ5: 2 | EA5: 0 | EB5: 1 | EC5: 1 | ED5: 2 | EE5: 1 | EF5: 1 | EG5: 2 | EH5: 1 | EI5: 1 | EJ5: 1 | EK5: 0 | EL5: 3 | EM5: 1 | EN5: 1 | EO5: 1 | EP5: 1 | EQ5: 1 | ER5: 2 | ES5: 0 | ET5: 2 | EU5: 0 | EV5: 1 | EW5: 1 | EX5: 0 | EY5: 0 | EZ5: 2 | FA5: 0 | FB5: 1 | FC5: 2 | FD5: 2 | FE5: 1 | FF5: 2 | FG5: 0 | FH5: 2 | FI5: 1 | FJ5: 1 | FK5: 2 | FL5: 2 | FM5: 3 | FN5: 0 | FO5: 1 | FP5: 1 | FQ5: 0 | FR5: 1 | FS5: 2 | FT5: 2 | FU5: 2 | FV5: 1 | FW5: 0 | FX5: 2 | FY5: 2 | FZ5: 1 | GA5: 1 | GB5: 2 | GC5: 0 | GD5: 1 | GE5: 1 | GF5: 1 | GG5: 1 | GH5: 0 | GI5: 0 | GJ5: 0 | GK5: 0 | GL5: 1 | GM5: 3 | GN5: 1 | GO5: 0 | GP5: 0 | GQ5: 3 | GR5: 0 | GS5: 1 | GT5: 0 | GU5: 0 | GV5: 0 | GW5: 3 | GX5: 4 | GY5: 0 | GZ5: 0 | HA5: 2 | HB5: 1 | HC5: 1 | HD5: 3 | HE5: 2 | HF5: 0 | HG5: 0 | HH5: 1 | HI5: 1 | HJ5: 1 | HK5: 1 | HL5: 1 | HM5: 1 | HN5: 1 | HO5: 2 | HP5: 0 | HQ5: 1 | HR5: 1 | HS5: 0 | HT5: 3 | HU5: 1 | HV5: 1 | HW5: 0 | HX5: 0 | HY5: 0 | HZ5: 0 | IA5: 0 | IB5: 1 | IC5: 3 | ID5: 2 | IE5: 1 | IF5: 2 | IG5: 0 | IH5: 2 | II5: 0 | IJ5: 0 | IK5: 0 | IL5: 1 | IM5: 0 | IN5: 0 | IO5: 0 | IP5: 2 | IQ5: 2 | IR5: 0 | IS5: 1 | IT5: 0 | IU5: 1 | IV5: 2 | IW5: 1 | IX5: 2 | IY5: 0 | IZ5: 1 | JA5: 0 | JB5: 1 | JC5: 0 | JD5: 0 | JE5: 0 | JF5: 0 | JG5: 1 | JH5: 1 | JI5: 1 | JJ5: 0 | JK5: 1 | JL5: 1 | JM5: 0 | JN5: 1 | JO5: 3 | JP5: 2 | JQ5: 0 | JR5: 2 | JS5: 2 | JT5: 0 | JU5: 2 | JV5: 1 | JW5: 0 | JX5: 2 | JY5: 0 | JZ5: 2 | KA5: 0 | KB5: 3 | KC5: 2 | KD5: 1 | KE5: 2 | KF5: 1 | KG5: 1 | KH5: 0 | KI5: 0 | KJ5: 1 | KK5: 0 | KL5: 0 | KM5: 0 | KN5: 2 | KO5: 0 | KP5: 0 | KQ5: 0 | KR5: 1 | KS5: 0 | KT5: 1 | KU5: 0 | KV5: 2 | KW5: 1 | KX5: 3 | KY5: 3 | KZ5: 0 | LA5: 1 | LB5: 0 | LC5: 2 | LD5: 0 | LE5: 0 | LF5: 1 | LG5: 0 | LH5: 2 | LI5: 2 | LJ5: 1 | LK5: 0 | LL5: 0 | LM5: 1 | LN5: 1 | LO5: 0 | LP5: 2 | LQ5: 0 | LR5: 4 | LS5: 2 | LT5: 1 | LU5: 0 | LV5: 2 | LW5: 0 | LX5: 0 | LY5: 1 | LZ5: 2 | MA5: 2 | MB5: 1 | MC5: 0 | MD5: 1 | ME5: 4 | MF5: 0 | MG5: 2 | MH5: 1 | MI5: 1 | MJ5: 3 | MK5: 1 | ML5: 3 | MM5: 3 | MN5: 1 | MO5: 0 | MP5: 0 | MQ5: 0 | MR5: 1 | MS5: 0 | MT5: 1 | MU5: 0 | MV5: 1 | MW5: 1 | MX5: 2 | MY5: 0 | MZ5: 3 | NA5: 1 | NB5: 1 | NC5: 2 | ND5: 2 | NE5: 1 | NF5: 0 | NG5: 0 | NH5: 1 | NI5: 0 | NJ5: 1 | NK5: 1 | NL5: 0 | NM5: 1 | NN5: 2 | NO5: 2 | NP5: 2 | NQ5: 2 | NR5: 1 | NS5: 1 | NT5: 0 | NU5: 3 | NV5: 0 | NW5: 2 | NX5: 2 | NY5: 1 | NZ5: 2 | OA5: 0 | OB5: 2 | OC5: 0 | OD5: 2 | OE5: 0 | OF5: 2 | OG5: 0 | OH5: 2 | OI5: 0 | OJ5: 0 | OK5: 0 | OL5: 1 | OM5: 1 | ON5: 0 | OO5: 1 | OP5: 0 | OQ5: 3 | OR5: 2 | OS5: 0 | OT5: 1 | OU5: 0 | OV5: 1 | OW5: 0 | OX5: 3 | OY5: 0 | OZ5: 0 | PA5: 1 | PB5: 1 | PC5: 1 | PD5: 2 | PE5: 1 | PF5: 0 | PG5: 1 | PH5: 3 | PI5: 0 | PJ5: 1 | PK5: 1 | PL5: 2 | PM5: 0 | PN5: 2 | PO5: 0 | PP5: 0 | PQ5: 0 | PR5: 1 | PS5: 1 | PT5: 0 | PU5: 2 | PV5: 0 | PW5: 1 | PX5: 0 | PY5: 2 | PZ5: 0 | QA5: 1 | QB5: 0 | QC5: 2 | QD5: 1 | QE5: 0 | QF5: 2 | QG5: 2 | QH5: 2 | QI5: 1 | QJ5: 0 | QK5: 1 | QL5: 2 | QM5: 1 | QN5: 0 | QO5: 1 | QP5: 2 | QQ5: 0 | QR5: 0 | QS5: 3 | QT5: 1 | QU5: 1 | QV5: 1 | QW5: 3 | QX5: 2 | QY5: 2 | QZ5: 2 | RA5: 2 | RB5: 1 | RC5: 0 | RD5: 0 | RE5: 2 | RF5: 0 | RG5: 1 | RH5: 1 | RI5: 1 | RJ5: 1 | RK5: 1 | RL5: 3 | RM5: 2 | RN5: 0 | RO5: 1 | RP5: 0 | RQ5: 0 | RR5: 0 | RS5: 1 | RT5: 0 | RU5: 3 | RV5: 0 | RW5: 3 | RX5: 2 | RY5: 2 | RZ5: 1 | SA5: 2 | SB5: 0 | SC5: 1 | SD5: 2 | SE5: 3 | SF5: 0 | SG5: 2
A6: R02 | B6: 1 | C6: 0 | D6: 2 | E6: 1 | F6: 1 | G6: 0 | H6: 0 | I6: 2 | J6: 1 | K6: 4 | L6: 1 | M6: 1 | N6: 1 | O6: 2 | P6: 0 | Q6: 1 | R6: 0 | S6: 2 | T6: 1 | U6: 0 | V6: 1 | W6: 1 | X6: 0 | Y6: 3 | Z6: 1 | AA6: 2 | AB6: 1 | AC6: 1 | AD6: 2 | AE6: 3 | AF6: 1 | AG6: 1 | AH6: 2 | AI6: 1 | AJ6: 0 | AK6: 1 | AL6: 1 | AM6: 1 | AN6: 0 | AO6: 1 | AP6: 1 | AQ6: 0 | AR6: 2 | AS6: 1 | AT6: 1 | AU6: 1 | AV6: 3 | AW6: 0 | AX6: 1 | AY6: 0 | AZ6: 0 | BA6: 2 | BB6: 2 | BC6: 2 | BD6: 0 | BE6: 1 | BF6: 2 | BG6: 0 | BH6: 0 | BI6: 3 | BJ6: 1 | BK6: 3 | BL6: 1 | BM6: 1 | BN6: 1 | BO6: 1 | BP6: 2 | BQ6: 0 | BR6: 0 | BS6: 1 | BT6: 2 | BU6: 0 | BV6: 1 | BW6: 0 | BX6: 1 | BY6: 0 | BZ6: 0 | CA6: 0 | CB6: 3 | CC6: 1 | CD6: 2 | CE6: 3 | CF6: 2 | CG6: 2 | CH6: 2 | CI6: 1 | CJ6: 1 | CK6: 0 | CL6: 0 | CM6: 1 | CN6: 1 | CO6: 1 | CP6: 0 | CQ6: 3 | CR6: 0 | CS6: 0 | CT6: 1 | CU6: 1 | CV6: 3 | CW6: 0 | CX6: 0 | CY6: 0 | CZ6: 4 | DA6: 1 | DB6: 2 | DC6: 0 | DD6: 0 | DE6: 3 | DF6: 0 | DG6: 2 | DH6: 1 | DI6: 2 | DJ6: 2 | DK6: 0 | DL6: 0 | DM6: 0 | DN6: 1 | DO6: 1 | DP6: 0 | DQ6: 1 | DR6: 2 | DS6: 1 | DT6: 1 | DU6: 0 | DV6: 1 | DW6: 1 | DX6: 4 | DY6: 0 | DZ6: 1 | EA6: 1 | EB6: 1 | EC6: 2 | ED6: 0 | EE6: 0 | EF6: 1 | EG6: 1 | EH6: 2 | EI6: 2 | EJ6: 3 | EK6: 3 | EL6: 0 | EM6: 1 | EN6: 2 | EO6: 1 | EP6: 0 | EQ6: 2 | ER6: 1 | ES6: 1 | ET6: 3 | EU6: 1 | EV6: 0 | EW6: 3 | EX6: 0 | EY6: 3 | EZ6: 0 | FA6: 2 | FB6: 1 | FC6: 2 | FD6: 1 | FE6: 0 | FF6: 1 | FG6: 0 | FH6: 1 | FI6: 2 | FJ6: 0 | FK6: 2 | FL6: 0 | FM6: 0 | FN6: 0 | FO6: 1 | FP6: 0 | FQ6: 1 | FR6: 0 | FS6: 0 | FT6: 1 | FU6: 0 | FV6: 3 | FW6: 1 | FX6: 1 | FY6: 3 | FZ6: 1 | GA6: 4 | GB6: 2 | GC6: 2 | GD6: 1 | GE6: 2 | GF6: 1 | GG6: 2 | GH6: 3 | GI6: 0 | GJ6: 2 | GK6: 0 | GL6: 1 | GM6: 1 | GN6: 1 | GO6: 1 | GP6: 1 | GQ6: 0 | GR6: 1 | GS6: 1 | GT6: 0 | GU6: 1 | GV6: 1 | GW6: 2 | GX6: 2 | GY6: 3 | GZ6: 3 | HA6: 1 | HB6: 1 | HC6: 1 | HD6: 0 | HE6: 1 | HF6: 1 | HG6: 0 | HH6: 1 | HI6: 1 | HJ6: 2 | HK6: 1 | HL6: 2 | HM6: 1 | HN6: 2 | HO6: 1 | HP6: 1 | HQ6: 1 | HR6: 1 | HS6: 1 | HT6: 1 | HU6: 1 | HV6: 1 | HW6: 0 | HX6: 1 | HY6: 0 | HZ6: 2 | IA6: 1 | IB6: 2 | IC6: 0 | ID6: 1 | IE6: 1 | IF6: 0 | IG6: 0 | IH6: 0 | II6: 0 | IJ6: 3 | IK6: 3 | IL6: 0 | IM6: 0 | IN6: 1 | IO6: 1 | IP6: 0 | IQ6: 2 | IR6: 2 | IS6: 1 | IT6: 2 | IU6: 0 | IV6: 2 | IW6: 0 | IX6: 1 | IY6: 2 | IZ6: 0 | JA6: 0 | JB6: 0 | JC6: 1 | JD6: 1 | JE6: 1 | JF6: 2 | JG6: 0 | JH6: 3 | JI6: 2 | JJ6: 1 | JK6: 1 | JL6: 1 | JM6: 0 | JN6: 1 | JO6: 2 | JP6: 1 | JQ6: 1 | JR6: 2 | JS6: 0 | JT6: 0 | JU6: 0 | JV6: 1 | JW6: 0 | JX6: 1 | JY6: 0 | JZ6: 2 | KA6: 2 | KB6: 0 | KC6: 0 | KD6: 1 | KE6: 1 | KF6: 1 | KG6: 2 | KH6: 0 | KI6: 0 | KJ6: 1 | KK6: 1 | KL6: 0 | KM6: 1 | KN6: 0 | KO6: 0 | KP6: 1 | KQ6: 2 | KR6: 1 | KS6: 1 | KT6: 2 | KU6: 1 | KV6: 1 | KW6: 0 | KX6: 0 | KY6: 0 | KZ6: 0 | LA6: 0 | LB6: 2 | LC6: 3 | LD6: 1 | LE6: 0 | LF6: 0 | LG6: 1 | LH6: 1 | LI6: 0 | LJ6: 0 | LK6: 1 | LL6: 1 | LM6: 1 | LN6: 0 | LO6: 0 | LP6: 2 | LQ6: 2 | LR6: 1 | LS6: 1 | LT6: 0 | LU6: 1 | LV6: 0 | LW6: 1 | LX6: 1 | LY6: 0 | LZ6: 2 | MA6: 1 | MB6: 1 | MC6: 1 | MD6: 0 | ME6: 0 | MF6: 0 | MG6: 3 | MH6: 0 | MI6: 1 | MJ6: 2 | MK6: 0 | ML6: 1 | MM6: 1 | MN6: 0 | MO6: 1 | MP6: 1 | MQ6: 1 | MR6: 0 | MS6: 0 | MT6: 0 | MU6: 2 | MV6: 3 | MW6: 2 | MX6: 2 | MY6: 1 | MZ6: 0 | NA6: 2 | NB6: 1 | NC6: 2 | ND6: 0 | NE6: 0 | NF6: 3 | NG6: 0 | NH6: 2 | NI6: 2 | NJ6: 0 | NK6: 1 | NL6: 1 | NM6: 1 | NN6: 0 | NO6: 2 | NP6: 2 | NQ6: 0 | NR6: 0 | NS6: 0 | NT6: 2 | NU6: 0 | NV6: 0 | NW6: 0 | NX6: 1 | NY6: 0 | NZ6: 1 | OA6: 2 | OB6: 1 | OC6: 1 | OD6: 0 | OE6: 0 | OF6: 1 | OG6: 2 | OH6: 1 | OI6: 2 | OJ6: 0 | OK6: 2 | OL6: 0 | OM6: 0 | ON6: 2 | OO6: 3 | OP6: 0 | OQ6: 1 | OR6: 1 | OS6: 2 | OT6: 3 | OU6: 1 | OV6: 1 | OW6: 1 | OX6: 0 | OY6: 3 | OZ6: 0 | PA6: 0 | PB6: 1 | PC6: 1 | PD6: 2 | PE6: 0 | PF6: 1 | PG6: 1 | PH6: 3 | PI6: 0 | PJ6: 0 | PK6: 1 | PL6: 2 | PM6: 2 | PN6: 0 | PO6: 1 | PP6: 2 | PQ6: 0 | PR6: 3 | PS6: 0 | PT6: 0 | PU6: 1 | PV6: 1 | PW6: 3 | PX6: 0 | PY6: 0 | PZ6: 1 | QA6: 1 | QB6: 0 | QC6: 1 | QD6: 0 | QE6: 2 | QF6: 0 | QG6: 1 | QH6: 2 | QI6: 0 | QJ6: 0 | QK6: 1 | QL6: 2 | QM6: 1 | QN6: 0 | QO6: 1 | QP6: 2 | QQ6: 2 | QR6: 2 | QS6: 1 | QT6: 0 | QU6: 2 | QV6: 0 | QW6: 0 | QX6: 2 | QY6: 0 | QZ6: 0 | RA6: 1 | RB6: 0 | RC6: 0 | RD6: 0 | RE6: 2 | RF6: 1 | RG6: 1 | RH6: 1 | RI6: 2 | RJ6: 0 | RK6: 2 | RL6: 0 | RM6: 1 | RN6: 1 | RO6: 0 | RP6: 1 | RQ6: 0 | RR6: 3 | RS6: 0 | RT6: 2 | RU6: 2 | RV6: 1 | RW6: 0 | RX6: 3 | RY6: 0 | RZ6: 0 | SA6: 1 | SB6: 2 | SC6: 1 | SD6: 1 | SE6: 0 | SF6: 2 | SG6: 1
